Workbook

Sheet ARPU
U2: Level | V2: ARPU AND | W2: ARPU IOS
U3: 1 | V3: =And!O3 -> 0.0034522786 | W3: =IOS!O3 -> 0.0076932668
U4: 2 | V4: =And!O4 -> 0.0017543094 | W4: =IOS!O4 -> 0.0029615385
U5: 3 | V5: =And!O5 -> 0.0017368305 | W5: =IOS!O5 -> 0.0030183727
U6: 4 | V6: =And!O6 -> 0.00050922837 | W6: =IOS!O6 -> 0
U7: 5 | V7: =And!O7 -> 0.00089394281 | W7: =IOS!O7 -> 0
U8: 6 | V8: =And!O8 -> 0.00090268304 | W8: =IOS!O8 -> 0.0030446549
U9: 7 | V9: =And!O9 -> 0.0013695802 | W9: =IOS!O9 -> 0.0027448276
U10: 8 | V10: =And!O10 -> 0.00046128883 | W10: =IOS!O10 -> 0
U11: 9 | V11: =And!O11 -> 0.00045560748 | W11: =IOS!O11 -> 0
U12: 10 | V12: =And!O12 -> 0.0043650794 | W12: =IOS!O12 -> 0
U13: 11 | V13: =And!O13 -> 0.0035943152 | W13: =IOS!O13 -> 0.014814815
U14: 12 | V14: =And!O14 -> 0.0055706892 | W14: =IOS!O14 -> 0
... U252: 250 | V252: =And!O252 -> 0.085315315 | W252: =IOS!O252 -> 0
U1001: 999
U1002: 1000
U1003: 1001
U1004: 1002
U1005: 1003
U1006: 1004
U1007: 1005
U1008: 1006
U1009: 1007
U1010: 1008
U1011: 1009
U1012: 1010
... U1215: 1213

Sheet Av.Rw
U2: Level | V2: AND_Avg Rwr | W2: IOS_Avg Rwr
U3: 1 | V3: =And!T3 -> 0.00064488392 | W3: =IOS!T3 -> 0
U4: 2 | V4: =And!T4 -> 0.00021819769 | W4: =IOS!T4 -> 0
U5: 3 | V5: =And!T5 -> 0.00066122989 | W5: =IOS!T5 -> 0
U6: 4 | V6: =And!T6 -> 0.00066711141 | W6: =IOS!T6 -> 0
U7: 5 | V7: =And!T7 -> 0.0011258726 | W7: =IOS!T7 -> 0.001345895
U8: 6 | V8: =And!T8 -> 0.0015916326 | W8: =IOS!T8 -> 0
U9: 7 | V9: =And!T9 -> 0.00068823125 | W9: =IOS!T9 -> 0
U10: 8 | V10: =And!T10 -> 0 | W10: =IOS!T10 -> 0.001396648
U11: 9 | V11: =And!T11 -> 0.0060747664 | W11: =IOS!T11 -> 0.0042432815
U12: 10 | V12: =And!T12 -> 0.0019240019 | W12: =IOS!T12 -> 0.0071736011
U13: 11 | V13: =And!T13 -> 0.19638243 | W13: =IOS!T13 -> 0.13734568
U14: 12 | V14: =And!T14 -> 0.13048216 | W14: =IOS!T14 -> 0.12280702
... U252: 250 | V252: =And!T252 -> 0.72972973 | W252: =IOS!T252 -> 0.84090909
U1001: 999
U1002: 1000
U1003: 1001
U1004: 1002
U1005: 1003
U1006: 1004
U1007: 1005
U1008: 1006
U1009: 1007
U1010: 1008
U1011: 1009
U1012: 1010
... U1215: 1213

Sheet And
A1: Segment | B1: Start | C1: Complete | D1: Fail | E1: Try again | L1: Complete | M1: LevelType | N1: =SUM(N3:N302) -> 5013.68 | O1: =(N1/C3)/300 -> 0.0035924907 | Q1: =AVERAGE(Q3:Q202) -> 0.26418814 | R1: =AVERAGE(R3:R202) -> 6.412887 | S1: =AVERAGE(S3:S402) -> 8.6987885 | T1: =AVERAGE(T13:T202) -> 0.49682256 | U1: =AVERAGE(U3:U402) -> 2208.581 | V1: =AVERAGE(V3:V402) -> 1.4573801e+08
A2: Level | B2: Active users | C2: Active users | D2: Active users | E2: Active users | F2: Complete rate | G2: Fail Rate | H2: Drop 1 | I2: Uncomplete | J2: Drop 2 | K2: % | L2: avarage_attempt | M2: LevelType | N2: Total $ | O2: ARPU | P2: %_used_booster | Q2: avg_used_booster | R2: avg_owned_booster | S2: Avg. Thinking Time | T2: Avg.Rewarded | U2: Avg,Coin | V2: coin owned
A3: 1 | B3: 4820 | C3: 4652 | D3: 155 | E3: 190 | F3: =(C3*100)/B3 -> 96.514523 | G3: =(D3*100)/B3 -> 3.2157676 | H3: =((B3-B4)/B3)*100 -> 3.5684647 | I3: =((B3-C3)/B3)*100 -> 3.4854772 | J3: =((C3-B4)/C3)*100 -> 0.085984523 | K3: =100-(((C3-C4)/C3)*100) -> 98.516767 | L3: 1.0083476 | M3: Normal | N3: 16.06 | O3: =N3/C3 -> 0.0034522786 | P3: =(Boosters_And!B3*100)/Boosters_And!N3 -> #DIV/0! | Q3: =Boosters_And!B3/(C3+D3) -> 0 | R3: =Boosters_And!N3/B3 -> 0 | S3: 0.2223887 | T3: 0.00064488392 | U3: 369.13156 | V3: 838400
A4: 2 | B4: 4648 | C4: 4583 | D4: 49 | E4: 70 | F4: =(C4*100)/B4 -> 98.601549 | G4: =(D4*100)/B4 -> 1.0542169 | H4: =((B4-B5)/B4)*100 -> 1.3123924 | I4: =((B4-C4)/B4)*100 -> 1.3984509 | J4: =((C4-B5)/C4)*100 -> -0.087279075 | K4: =100-(((C3-C5)/C3)*100) -> 97.527945 | L4: 1.002173 | M4: Normal | N4: 8.04 | O4: =N4/C4 -> 0.0017543094 | P4: =(Boosters_And!B4*100)/Boosters_And!N4 -> #DIV/0! | Q4: =Boosters_And!B4/(C4+D4) -> 0 | R4: =Boosters_And!N4/B4 -> 0 | S4: 0.017383746 | T4: 0.00021819769 | U4: 412.12721 | V4: 877950
A5: 3 | B5: 4587 | C5: 4537 | D5: 52 | E5: 81 | F5: =(C5*100)/B5 -> 98.909963 | G5: =(D5*100)/B5 -> 1.1336385 | H5: =((B5-B6)/B5)*100 -> 0.76302594 | I5: =((B5-C5)/B5)*100 -> 1.0900371 | J5: =((C5-B6)/C5)*100 -> -0.33061494 | K5: =100-(((C3-C6)/C3)*100) -> 96.6681 | L5: 1.0019754 | M5: Normal | N5: 7.88 | O5: =N5/C5 -> 0.0017368305 | P5: =(Boosters_And!B5*100)/Boosters_And!N5 -> #DIV/0! | Q5: =Boosters_And!B5/(C5+D5) -> 0 | R5: =Boosters_And!N5/B5 -> 0 | S5: 6.072432 | T5: 0.00066122989 | U5: 454.85078 | V5: 917710
A6: 4 | B6: 4552 | C6: 4497 | D6: 87 | E6: 110 | F6: =(C6*100)/B6 -> 98.79174 | G6: =(D6*100)/B6 -> 1.9112478 | H6: =((B6-B7)/B6)*100 -> 0.79086116 | I6: =((B6-C6)/B6)*100 -> 1.2082601 | J6: =((C6-B7)/C6)*100 -> -0.42250389 | K6: =100-(((C3-C7)/C3)*100) -> 95.464316 | L6: 1.0033208 | M6: Normal | N6: 2.29 | O6: =N6/C6 -> 0.00050922837 | P6: =(Boosters_And!B6*100)/Boosters_And!N6 -> #DIV/0! | Q6: =Boosters_And!B6/(C6+D6) -> 0 | R6: =Boosters_And!N6/B6 -> 0 | S6: 5.5415099 | T6: 0.00066711141 | U6: 498.90749 | V6: 970730
A7: 5 | B7: 4516 | C7: 4441 | D7: 118 | E7: 152 | F7: =(C7*100)/B7 -> 98.339238 | G7: =(D7*100)/B7 -> 2.6129318 | H7: =((B7-B8)/B7)*100 -> 1.085031 | I7: =((B7-C7)/B7)*100 -> 1.6607617 | J7: =((C7-B8)/C7)*100 -> -0.58545373 | K7: =100-(((C3-C8)/C3)*100) -> 94.539983 | L7: 1.003585 | M7: Normal | N7: 3.97 | O7: =N7/C7 -> 0.00089394281 | P7: =(Boosters_And!B7*100)/Boosters_And!N7 -> #DIV/0! | Q7: =Boosters_And!B7/(C7+D7) -> 0 | R7: =Boosters_And!N7/B7 -> 0 | S7: 5.329823 | T7: 0.0011258726 | U7: 572.3524 | V7: 1011470
A8: 6 | B8: 4467 | C8: 4398 | D8: 156 | E8: 193 | F8: =(C8*100)/B8 -> 98.455339 | G8: =(D8*100)/B8 -> 3.4922767 | H8: =((B8-B9)/B8)*100 -> 1.2760242 | I8: =((B8-C8)/B8)*100 -> 1.5446608 | J8: =((C8-B9)/C8)*100 -> -0.2728513 | K8: =100-(((C3-C9)/C3)*100) -> 93.701634 | L8: 1.0070167 | M8: Normal | N8: 3.97 | O8: =N8/C8 -> 0.00090268304 | P8: =(Boosters_And!B8*100)/Boosters_And!N8 -> #DIV/0! | Q8: =Boosters_And!B8/(C8+D8) -> 0 | R8: =Boosters_And!N8/B8 -> 0 | S8: 5.4916252 | T8: 0.0015916326 | U8: 593.93292 | V8: 1037160
A9: 7 | B9: 4410 | C9: 4359 | D9: 115 | E9: 162 | F9: =(C9*100)/B9 -> 98.843537 | G9: =(D9*100)/B9 -> 2.6077098 | H9: =((B9-B10)/B9)*100 -> 0.88435374 | I9: =((B9-C9)/B9)*100 -> 1.1564626 | J9: =((C9-B10)/C9)*100 -> -0.2752925 | K9: =100-(((C3-C10)/C3)*100) -> 92.734308 | L9: 1.0022852 | M9: Normal | N9: 5.97 | O9: =N9/C9 -> 0.0013695802 | P9: =(Boosters_And!B9*100)/Boosters_And!N9 -> #DIV/0! | Q9: =Boosters_And!B9/(C9+D9) -> 0 | R9: =Boosters_And!N9/B9 -> 0 | S9: 6.523766 | T9: 0.00068823125 | U9: 615.1404 | V9: 1061800
A10: 8 | B10: 4371 | C10: 4314 | D10: 76 | E10: 112 | F10: =(C10*100)/B10 -> 98.695951 | G10: =(D10*100)/B10 -> 1.7387326 | H10: =((B10-B11)/B10)*100 -> 0.4575612 | I10: =((B10-C10)/B10)*100 -> 1.3040494 | J10: =((C10-B11)/C10)*100 -> -0.85767269 | K10: =100-(((C3-C11)/C3)*100) -> 92.003439 | L10: 1.0016174 | M10: Normal | N10: 1.99 | O10: =N10/C10 -> 0.00046128883 | P10: =(Boosters_And!B10*100)/Boosters_And!N10 -> 95.928704 | Q10: =Boosters_And!B10/(C10+D10) -> 0.97588392 | R10: =Boosters_And!N10/B10 -> 1.0217233 | S10: 5.5894177 | T10: 0 | U10: 636.29972 | V10: 1101080
A11: 9 | B11: 4351 | C11: 4280 | D11: 227 | E11: 276 | F11: =(C11*100)/B11 -> 98.368191 | G11: =(D11*100)/B11 -> 5.2171915 | H11: =((B11-B12)/B11)*100 -> 3.7692484 | I11: =((B11-C11)/B11)*100 -> 1.6318088 | J11: =((C11-B12)/C11)*100 -> 2.1728972 | K11: =100-(((C3-C12)/C3)*100) -> 89.380911 | L11: 1.0221497 | M11: Normal | N11: 1.95 | O11: =N11/C11 -> 0.00045560748 | P11: =(Boosters_And!B11*100)/Boosters_And!N11 -> 2.2220919 | Q11: =Boosters_And!B11/(C11+D11) -> 0.021859683 | R11: =Boosters_And!N11/B11 -> 1.0190144 | S11: 6.7307065 | T11: 0.0060747664 | U11: 655.48294 | V11: 1137970
A12: 10 | B12: 4187 | C12: 4158 | D12: 85 | E12: 82 | F12: =(C12*100)/B12 -> 99.30738 | G12: =(D12*100)/B12 -> 2.0300931 | H12: =((B12-B13)/B12)*100 -> 2.9615476 | I12: =((B12-C12)/B12)*100 -> 0.69262001 | J12: =((C12-B13)/C12)*100 -> 2.2847523 | K12: =100-(((C3-C13)/C3)*100) -> 83.190026 | L12: 1.0131989 | M12: Normal | N12: 18.15 | O12: =N12/C12 -> 0.0043650794 | P12: =(Boosters_And!B12*100)/Boosters_And!N12 -> 1.4098808 | Q12: =Boosters_And!B12/(C12+D12) -> 0.013669573 | R12: =Boosters_And!N12/B12 -> 0.98252281 | S12: 3.675546 | T12: 0.0019240019 | U12: 681.34848 | V12: 1143160
A13: 11 | B13: 4063 | C13: 3870 | D13: 1199 | E13: 725 | F13: =(C13*100)/B13 -> 95.249815 | G13: =(D13*100)/B13 -> 29.510214 | H13: =((B13-B14)/B13)*100 -> 9.0081221 | I13: =((B13-C13)/B13)*100 -> 4.7501846 | J13: =((C13-B14)/C13)*100 -> 4.4702842 | K13: =100-(((C3-C14)/C3)*100) -> 78.912296 | L13: 1.1562904 | M13: Normal | N13: 13.91 | O13: =N13/C13 -> 0.0035943152 | P13: =(Boosters_And!B13*100)/Boosters_And!N13 -> 5.8276945 | Q13: =Boosters_And!B13/(C13+D13) -> 0.059037104 | R13: =Boosters_And!N13/B13 -> 1.2638739 | S13: 4.1601653 | T13: 0.19638243 | U13: 1014.5109 | V13: 1724540
A14: 12 | B14: 3697 | C14: 3671 | D14: 27 | E14: 30 | F14: =(C14*100)/B14 -> 99.296727 | G14: =(D14*100)/B14 -> 0.73032188 | H14: =((B14-B15)/B14)*100 -> 2.9753854 | I14: =((B14-C14)/B14)*100 -> 0.70327292 | J14: =((C14-B15)/C14)*100 -> 2.2882048 | K14: =100-(((C3-C15)/C3)*100) -> 76.956148 | L14: 1.0013613 | M14: Normal | N14: 20.45 | O14: =N14/C14 -> 0.0055706892 | P14: =(Boosters_And!B14*100)/Boosters_And!N14 -> 53.302475 | Q14: =Boosters_And!B14/(C14+D14) -> 1.012204 | R14: =Boosters_And!N14/B14 -> 1.8994949 | S14: 0.0087122243 | T14: 0.13048216 | U14: 1166.6156 | V14: 1800950
A15: 13 | B15: 3587 | C15: 3580 | D15: 8 | E15: 16 | F15: =(C15*100)/B15 -> 99.804851 | G15: =(D15*100)/B15 -> 0.2230276 | H15: =((B15-B16)/B15)*100 -> 0.91998885 | I15: =((B15-C15)/B15)*100 -> 0.19514915 | J15: =((C15-B16)/C15)*100 -> 0.72625698 | K15: =100-(((C3-C16)/C3)*100) -> 74.419604 | L15: 1.0013966 | M15: Normal | N15: 15.96 | O15: =N15/C15 -> 0.0044581006 | P15: =(Boosters_And!B15*100)/Boosters_And!N15 -> 0.60470043 | Q15: =Boosters_And!B15/(C15+D15) -> 0.011426979 | R15: =Boosters_And!N15/B15 -> 1.8902193 | S15: 8.5924581 | T15: 0.13575419 | U15: 1244.1969 | V15: 1861170
A16: 14 | B16: 3554 | C16: 3462 | D16: 1255 | E16: 713 | F16: =(C16*100)/B16 -> 97.411367 | G16: =(D16*100)/B16 -> 35.312324 | H16: =((B16-B17)/B16)*100 -> 4.07991 | I16: =((B16-C16)/B16)*100 -> 2.5886325 | J16: =((C16-B17)/C16)*100 -> 1.530907 | K16: =100-(((C3-C17)/C3)*100) -> 72.979364 | L16: 1.2229281 | M16: Hard | N16: 11.97 | O16: =N16/C16 -> 0.003457539 | P16: =(Boosters_And!B16*100)/Boosters_And!N16 -> 2.2466745 | Q16: =Boosters_And!B16/(C16+D16) -> 0.047219978 | R16: =Boosters_And!N16/B16 -> 2.7895494 | S16: 3.1131967 | T16: 0.15569035 | U16: 1154.1667 | V16: 1713930
A17: 15 | B17: 3409 | C17: 3395 | D17: 124 | E17: 90 | F17: =(C17*100)/B17 -> 99.589322 | G17: =(D17*100)/B17 -> 3.6374303 | H17: =((B17-B18)/B17)*100 -> 1.7013787 | I17: =((B17-C17)/B17)*100 -> 0.41067762 | J17: =((C17-B18)/C17)*100 -> 1.2960236 | K17: =100-(((C3-C18)/C3)*100) -> 71.195185 | L17: 1.0197349 | M17: Normal | N17: 17.47 | O17: =N17/C17 -> 0.0051458027 | P17: =(Boosters_And!B17*100)/Boosters_And!N17 -> 1.2886792 | Q17: =Boosters_And!B17/(C17+D17) -> 0.023771522 | R17: =Boosters_And!N17/B17 -> 1.9041643 | S17: 3.9661267 | T17: 0.13608247 | U17: 1191.0884 | V17: 1745140
A18: 16 | B18: 3351 | C18: 3312 | D18: 227 | E18: 191 | F18: =(C18*100)/B18 -> 98.836168 | G18: =(D18*100)/B18 -> 6.7740973 | H18: =((B18-B19)/B18)*100 -> 2.8648165 | I18: =((B18-C18)/B18)*100 -> 1.1638317 | J18: =((C18-B19)/C18)*100 -> 1.7210145 | K18: =100-(((C3-C19)/C3)*100) -> 69.561479 | L18: 1.0138889 | M18: Normal | N18: 3.98 | O18: =N18/C18 -> 0.0012016908 | P18: =(Boosters_And!B18*100)/Boosters_And!N18 -> 32.885496 | Q18: =Boosters_And!B18/(C18+D18) -> 0.9624788 | R18: =Boosters_And!N18/B18 -> 3.0909566 | S18: 0.28562802 | T18: 0.13586957 | U18: 1290.4272 | V18: 1798900
A19: 17 | B19: 3255 | C19: 3236 | D19: 147 | E19: 99 | F19: =(C19*100)/B19 -> 99.416283 | G19: =(D19*100)/B19 -> 4.516129 | H19: =((B19-B20)/B19)*100 -> 1.3517665 | I19: =((B19-C19)/B19)*100 -> 0.58371736 | J19: =((C19-B20)/C19)*100 -> 0.77255871 | K19: =100-(((C3-C20)/C3)*100) -> 68.873603 | L19: 1.026267 | M19: Normal | N19: 24.97 | O19: =N19/C19 -> 0.0077163164 | P19: =(Boosters_And!B19*100)/Boosters_And!N19 -> 0.77824518 | Q19: =Boosters_And!B19/(C19+D19) -> 0.022285307 | R19: =Boosters_And!N19/B19 -> 2.9761388 | S19: 5.592707 | T19: 0.13195303 | U19: 1360.1032 | V19: 1811970
A20: 18 | B20: 3211 | C20: 3204 | D20: 17 | E20: 19 | F20: =(C20*100)/B20 -> 99.781999 | G20: =(D20*100)/B20 -> 0.52943008 | H20: =((B20-B21)/B20)*100 -> 1.4948614 | I20: =((B20-C20)/B20)*100 -> 0.21800062 | J20: =((C20-B21)/C20)*100 -> 1.2796504 | K20: =100-(((C3-C21)/C3)*100) -> 67.734308 | L20: 1.0012484 | M20: Normal | N20: 16.91 | O20: =N20/C20 -> 0.0052777778 | P20: =(Boosters_And!B20*100)/Boosters_And!N20 -> 0.2831212 | Q20: =Boosters_And!B20/(C20+D20) -> 0.0080720273 | R20: =Boosters_And!N20/B20 -> 2.8599646 | S20: 4.301186 | T20: 0.1298377 | U20: 1395.716 | V20: 1825480
A21: 19 | B21: 3163 | C21: 3151 | D21: 27 | E21: 31 | F21: =(C21*100)/B21 -> 99.620613 | G21: =(D21*100)/B21 -> 0.85361998 | H21: =((B21-B22)/B21)*100 -> 1.2013911 | I21: =((B21-C21)/B21)*100 -> 0.37938666 | J21: =((C21-B22)/C21)*100 -> 0.82513488 | K21: =100-(((C3-C22)/C3)*100) -> 66.487532 | L21: 1.0019042 | M21: Normal | N21: 23.34 | O21: =N21/C21 -> 0.0074071723 | P21: =(Boosters_And!B21*100)/Boosters_And!N21 -> 0.51555503 | Q21: =Boosters_And!B21/(C21+D21) -> 0.014789176 | R21: =Boosters_And!N21/B21 -> 2.8821968 | S21: 4.1888289 | T21: 0.25706125 | U21: 1460.8232 | V21: 1852880
A22: 20 | B22: 3125 | C22: 3093 | D22: 262 | E22: 143 | F22: =(C22*100)/B22 -> 98.976 | G22: =(D22*100)/B22 -> 8.384 | H22: =((B22-B23)/B22)*100 -> 3.52 | I22: =((B22-C22)/B22)*100 -> 1.024 | J22: =((C22-B23)/C22)*100 -> 2.5218235 | K22: =100-(((C3-C23)/C3)*100) -> 64.531384 | L22: 1.018752 | M22: Normal | N22: 8.92 | O22: =N22/C22 -> 0.0028839315 | P22: =(Boosters_And!B22*100)/Boosters_And!N22 -> 6.6007974 | Q22: =Boosters_And!B22/(C22+D22) -> 0.18147972 | R22: =Boosters_And!N22/B22 -> 2.9517135 | S22: 5.3789201 | T22: 0.16521177 | U22: 1506.4704 | V22: 1794150
A23: 21 | B23: 3015 | C23: 3002 | D23: 33 | E23: 38 | F23: =(C23*100)/B23 -> 99.568823 | G23: =(D23*100)/B23 -> 1.0945274 | H23: =((B23-B24)/B23)*100 -> 2.6865672 | I23: =((B23-C23)/B23)*100 -> 0.43117745 | J23: =((C23-B24)/C23)*100 -> 2.2651566 | K23: =100-(((C3-C24)/C3)*100) -> 62.940671 | L23: 1.001998 | M23: Normal | N23: 9.46 | O23: =N23/C23 -> 0.0031512325 | P23: =(Boosters_And!B23*100)/Boosters_And!N23 -> 1.8381008 | Q23: =Boosters_And!B23/(C23+D23) -> 0.050497791 | R23: =Boosters_And!N23/B23 -> 2.765505 | S23: 4.3233433 | T23: 0.34110593 | U23: 1579.958 | V23: 1888830
A24: 22 | B24: 2934 | C24: 2928 | D24: 34 | E24: 31 | F24: =(C24*100)/B24 -> 99.795501 | G24: =(D24*100)/B24 -> 1.1588275 | H24: =((B24-B25)/B24)*100 -> 0.68166326 | I24: =((B24-C24)/B24)*100 -> 0.20449898 | J24: =((C24-B25)/C24)*100 -> 0.47814208 | K24: =100-(((C3-C25)/C3)*100) -> 61.134996 | L24: 1.0023899 | M24: Normal | N24: 20.62 | O24: =N24/C24 -> 0.0070423497 | P24: =(Boosters_And!B24*100)/Boosters_And!N24 -> 0.62409905 | Q24: =Boosters_And!B24/(C24+D24) -> 0.017218096 | R24: =Boosters_And!N24/B24 -> 2.785201 | S24: 4.1850461 | T24: 0.16905738 | U24: 1635.1755 | V24: 1909210
A25: 23 | B25: 2914 | C25: 2844 | D25: 709 | E25: 355 | F25: =(C25*100)/B25 -> 97.597804 | G25: =(D25*100)/B25 -> 24.330817 | H25: =((B25-B26)/B25)*100 -> 3.0885381 | I25: =((B25-C25)/B25)*100 -> 2.4021963 | J25: =((C25-B26)/C25)*100 -> 0.70323488 | K25: =100-(((C3-C26)/C3)*100) -> 60.038693 | L25: 1.1251318 | M25: Hard | N25: 11.48 | O25: =N25/C25 -> 0.0040365682 | P25: =(Boosters_And!B25*100)/Boosters_And!N25 -> 18.468172 | Q25: =Boosters_And!B25/(C25+D25) -> 0.48006965 | R25: =Boosters_And!N25/B25 -> 3.1694653 | S25: 5.7697715 | T25: 0.21308017 | U25: 1526.8196 | V25: 1760660
A26: 24 | B26: 2824 | C26: 2793 | D26: 381 | E26: 233 | F26: =(C26*100)/B26 -> 98.902266 | G26: =(D26*100)/B26 -> 13.491501 | H26: =((B26-B27)/B26)*100 -> 2.1246459 | I26: =((B26-C26)/B26)*100 -> 1.0977337 | J26: =((C26-B27)/C26)*100 -> 1.0383101 | K26: =100-(((C3-C27)/C3)*100) -> 59.329321 | L26: 1.0547602 | M26: Normal | N26: 26.25 | O26: =N26/C26 -> 0.0093984962 | P26: =(Boosters_And!B26*100)/Boosters_And!N26 -> 12.571264 | Q26: =Boosters_And!B26/(C26+D26) -> 0.26704643 | R26: =Boosters_And!N26/B26 -> 2.3875367 | S26: 3.8228346 | T26: 0.20085929 | U26: 1599.3 | V26: 1795500
A27: 25 | B27: 2764 | C27: 2760 | D27: 11 | E27: 16 | F27: =(C27*100)/B27 -> 99.855282 | G27: =(D27*100)/B27 -> 0.39797395 | H27: =((B27-B28)/B27)*100 -> 2.0622287 | I27: =((B27-C27)/B27)*100 -> 0.1447178 | J27: =((C27-B28)/C27)*100 -> 1.9202899 | K27: =100-(((C3-C28)/C3)*100) -> 58.104041 | L27: 1.0014488 | M27: Normal | N27: 5.95 | O27: =N27/C27 -> 0.0021557971 | P27: =(Boosters_And!B27*100)/Boosters_And!N27 -> 0.051894144 | Q27: =Boosters_And!B27/(C27+D27) -> 0.0010826416 | R27: =Boosters_And!N27/B27 -> 2.0915337 | S27: 7.2448388 | T27: 0.15326087 | U27: 1649.7989 | V27: 1840030
A28: 26 | B28: 2707 | C28: 2703 | D28: 7 | E28: 8 | F28: =(C28*100)/B28 -> 99.852235 | G28: =(D28*100)/B28 -> 0.25858884 | H28: =((B28-B29)/B28)*100 -> 0.36941263 | I28: =((B28-C28)/B28)*100 -> 0.14776505 | J28: =((C28-B29)/C28)*100 -> 0.22197558 | K28: =100-(((C3-C29)/C3)*100) -> 56.685297 | L28: 1.0014787 | M28: Normal | N28: 0 | O28: =N28/C28 -> 0 | P28: =(Boosters_And!B28*100)/Boosters_And!N28 -> 0.035184607 | Q28: =Boosters_And!B28/(C28+D28) -> 0.00073800738 | R28: =Boosters_And!N28/B28 -> 2.0998537 | S28: 2.607024 | T28: 0.1509434 | U28: 1697.1865 | V28: 1864890
A29: 27 | B29: 2697 | C29: 2637 | D29: 827 | E29: 397 | F29: =(C29*100)/B29 -> 97.775306 | G29: =(D29*100)/B29 -> 30.6637 | H29: =((B29-B30)/B29)*100 -> 3.2628847 | I29: =((B29-C29)/B29)*100 -> 2.2246941 | J29: =((C29-B30)/C29)*100 -> 1.0618127 | K29: =100-(((C3-C30)/C3)*100) -> 56.083405 | L29: 1.1891585 | M29: Normal | N29: 8.47 | O29: =N29/C29 -> 0.0032119833 | P29: =(Boosters_And!B29*100)/Boosters_And!N29 -> 0.77035076 | Q29: =Boosters_And!B29/(C29+D29) -> 0.018099067 | R29: =Boosters_And!N29/B29 -> 3.0176204 | S29: 3.0163002 | T29: 0.18012893 | U29: 1578.6219 | V29: 1707120
A30: 28 | B30: 2609 | C30: 2609 | D30: 24 | E30: 23 | F30: =(C30*100)/B30 -> 100 | G30: =(D30*100)/B30 -> 0.91989268 | H30: =((B30-B31)/B30)*100 -> 0.9965504 | I30: =((B30-C30)/B30)*100 -> 0 | J30: =((C30-B31)/C30)*100 -> 0.9965504 | K30: =100-(((C3-C31)/C3)*100) -> 55.395529 | L30: 1.0015326 | M30: Normal | N30: 16.01 | O30: =N30/C30 -> 0.0061364507 | P30: =(Boosters_And!B30*100)/Boosters_And!N30 -> 0.12506607 | Q30: =Boosters_And!B30/(C30+D30) -> 0.0026585644 | R30: =Boosters_And!N30/B30 -> 2.1452823 | S30: 3.4681992 | T30: 0.15024914 | U30: 1654.6363 | V30: 1758230
A31: 29 | B31: 2583 | C31: 2577 | D31: 90 | E31: 52 | F31: =(C31*100)/B31 -> 99.767712 | G31: =(D31*100)/B31 -> 3.4843206 | H31: =((B31-B32)/B31)*100 -> 0.46457607 | I31: =((B31-C31)/B31)*100 -> 0.23228804 | J31: =((C31-B32)/C31)*100 -> 0.23282887 | K31: =100-(((C3-C32)/C3)*100) -> 54.66466 | L31: 1.015128 | M31: Normal | N31: 5.96 | O31: =N31/C31 -> 0.0023127668 | P31: =(Boosters_And!B31*100)/Boosters_And!N31 -> 0.26240756 | Q31: =Boosters_And!B31/(C31+D31) -> 0.0056731899 | R31: =Boosters_And!N31/B31 -> 2.2322847 | S31: 3.8052754 | T31: 0.14823438 | U31: 1662.2689 | V31: 1778870
A32: 30 | B32: 2571 | C32: 2543 | D32: 192 | E32: 106 | F32: =(C32*100)/B32 -> 98.91093 | G32: =(D32*100)/B32 -> 7.4679113 | H32: =((B32-B33)/B32)*100 -> 1.9447686 | I32: =((B32-C32)/B32)*100 -> 1.0890704 | J32: =((C32-B33)/C32)*100 -> 0.86511994 | K32: =100-(((C3-C33)/C3)*100) -> 52.515047 | L32: 1.0334119 | M32: Normal | N32: 2.22 | O32: =N32/C32 -> 0.00087298466 | P32: =(Boosters_And!B32*100)/Boosters_And!N32 -> 0.54110057 | Q32: =Boosters_And!B32/(C32+D32) -> 0.011795537 | R32: =Boosters_And!N32/B32 -> 2.3189693 | S32: 4.6584119 | T32: 0.16397955 | U32: 1678.6775 | V32: 1774020
A33: 31 | B33: 2521 | C33: 2443 | D33: 1054 | E33: 475 | F33: =(C33*100)/B33 -> 96.90599 | G33: =(D33*100)/B33 -> 41.808806 | H33: =((B33-B34)/B33)*100 -> 4.3236811 | I33: =((B33-C33)/B33)*100 -> 3.0940103 | J33: =((C33-B34)/C33)*100 -> 1.2689316 | K33: =100-(((C3-C34)/C3)*100) -> 50.902837 | L33: 1.2030291 | M33: Normal | N33: 13.92 | O33: =N33/C33 -> 0.0056979124 | P33: =(Boosters_And!B33*100)/Boosters_And!N33 -> 0.74485424 | Q33: =Boosters_And!B33/(C33+D33) -> 0.018922956 | R33: =Boosters_And!N33/B33 -> 3.5240371 | S33: 4.5792059 | T33: 0.2022104 | U33: 1547.6574 | V33: 1569700
A34: 32 | B34: 2412 | C34: 2368 | D34: 396 | E34: 202 | F34: =(C34*100)/B34 -> 98.175788 | G34: =(D34*100)/B34 -> 16.41791 | H34: =((B34-B35)/B34)*100 -> 2.8606965 | I34: =((B34-C34)/B34)*100 -> 1.8242123 | J34: =((C34-B35)/C34)*100 -> 1.0557432 | K34: =100-(((C3-C35)/C3)*100) -> 47.656922 | L34: 1.0675676 | M34: Normal | N34: 11.47 | O34: =N34/C34 -> 0.00484375 | P34: =(Boosters_And!B34*100)/Boosters_And!N34 -> 2.3684027 | Q34: =Boosters_And!B34/(C34+D34) -> 0.053608386 | R34: =Boosters_And!N34/B34 -> 2.5938086 | S34: 8.0375845 | T34: 0.1875 | U34: 1576.234 | V34: 1522560
A35: 33 | B35: 2343 | C35: 2217 | D35: 652 | E35: 417 | F35: =(C35*100)/B35 -> 94.622279 | G35: =(D35*100)/B35 -> 27.827571 | H35: =((B35-B36)/B35)*100 -> 5.8045241 | I35: =((B35-C35)/B35)*100 -> 5.3777209 | J35: =((C35-B36)/C35)*100 -> 0.45105999 | K35: =100-(((C3-C36)/C3)*100) -> 45.077386 | L35: 1.2467298 | M35: Normal | N35: 43.99 | O35: =N35/C35 -> 0.019842129 | P35: =(Boosters_And!B35*100)/Boosters_And!N35 -> 2.7462001 | Q35: =Boosters_And!B35/(C35+D35) -> 0.080589917 | R35: =Boosters_And!N35/B35 -> 3.5934102 | S35: 4.2471809 | T35: 0.23725756 | U35: 1546.4172 | V35: 1484120
A36: 34 | B36: 2207 | C36: 2097 | D36: 388 | E36: 263 | F36: =(C36*100)/B36 -> 95.015859 | G36: =(D36*100)/B36 -> 17.580426 | H36: =((B36-B37)/B36)*100 -> 4.8482102 | I36: =((B36-C36)/B36)*100 -> 4.9841414 | J36: =((C36-B37)/C36)*100 -> -0.14306152 | K36: =100-(((C3-C37)/C3)*100) -> 44.582975 | L36: 1.2607245 | M36: Normal | N36: 49.41 | O36: =N36/C36 -> 0.023562232 | P36: =(Boosters_And!B36*100)/Boosters_And!N36 -> 8.6660755 | Q36: =Boosters_And!B36/(C36+D36) -> 0.23414758 | R36: =Boosters_And!N36/B36 -> 3.0422246 | S36: 4.7974261 | T36: 0.24225083 | U36: 1614.6338 | V36: 1504705
A37: 35 | B37: 2100 | C37: 2074 | D37: 407 | E37: 197 | F37: =(C37*100)/B37 -> 98.761905 | G37: =(D37*100)/B37 -> 19.380952 | H37: =((B37-B38)/B37)*100 -> 2.047619 | I37: =((B37-C37)/B37)*100 -> 1.2380952 | J37: =((C37-B38)/C37)*100 -> 0.81967213 | K37: =100-(((C3-C38)/C3)*100) -> 44.217541 | L37: 1.0987952 | M37: Normal | N37: 11.97 | O37: =N37/C37 -> 0.0057714561 | P37: =(Boosters_And!B37*100)/Boosters_And!N37 -> 1.088268 | Q37: =Boosters_And!B37/(C37+D37) -> 0.02509504 | R37: =Boosters_And!N37/B37 -> 2.7243286 | S37: 4.8428916 | T37: 0.19575699 | U37: 1600.5988 | V37: 1464415
A38: 36 | B38: 2057 | C38: 2057 | D38: 11 | E38: 13 | F38: =(C38*100)/B38 -> 100 | G38: =(D38*100)/B38 -> 0.53475936 | H38: =((B38-B39)/B38)*100 -> 1.1181332 | I38: =((B38-C38)/B38)*100 -> 0 | J38: =((C38-B39)/C38)*100 -> 1.1181332 | K38: =100-(((C3-C39)/C3)*100) -> 43.680138 | L38: 1.0004859 | M38: Normal | N38: 9.95 | O38: =N38/C38 -> 0.0048371415 | P38: =(Boosters_And!B38*100)/Boosters_And!N38 -> 0.32939026 | Q38: =Boosters_And!B38/(C38+D38) -> 0.0072533849 | R38: =Boosters_And!N38/B38 -> 2.2138399 | S38: 8.0758017 | T38: 0.17258143 | U38: 1675.5017 | V38: 1476400
A39: 37 | B39: 2034 | C39: 2032 | D39: 9 | E39: 7 | F39: =(C39*100)/B39 -> 99.901672 | G39: =(D39*100)/B39 -> 0.44247788 | H39: =((B39-B40)/B39)*100 -> 0.44247788 | I39: =((B39-C39)/B39)*100 -> 0.098328417 | J39: =((C39-B40)/C39)*100 -> 0.34448819 | K39: =100-(((C3-C40)/C3)*100) -> 43.422184 | L39: 1 | M39: Normal | N39: 15.96 | O39: =N39/C39 -> 0.0078543307 | P39: =(Boosters_And!B39*100)/Boosters_And!N39 -> 0.31849264 | Q39: =Boosters_And!B39/(C39+D39) -> 0.0073066059 | R39: =Boosters_And!N39/B39 -> 2.302016 | S39: 3.2705362 | T39: 0.16929134 | U39: 1734.3784 | V39: 1489390
A40: 38 | B40: 2025 | C40: 2020 | D40: 18 | E40: 16 | F40: =(C40*100)/B40 -> 99.753086 | G40: =(D40*100)/B40 -> 0.88888889 | H40: =((B40-B41)/B40)*100 -> -4.0987654 | I40: =((B40-C40)/B40)*100 -> 0.24691358 | J40: =((C40-B41)/C40)*100 -> -4.3564356 | K40: =100-(((C3-C41)/C3)*100) -> 40.455718 | L40: 1.002474 | M40: Normal | N40: 34.93 | O40: =N40/C40 -> 0.017292079 | P40: =(Boosters_And!B40*100)/Boosters_And!N40 -> 0.20085939 | Q40: =Boosters_And!B40/(C40+D40) -> 0.0049067713 | R40: =Boosters_And!N40/B40 -> 2.4585714 | S40: 3.8476002 | T40: 0.16980198 | U40: 1827.2287 | V40: 1529905
...

Sheet Boosters_And
A1: Segment | C1: Complete | D1: Complete | E1: Complete | F1: Fail | G1: Fail | H1: Fail | J1: Complete | K1: Column 1 | L1: Column 2 | M1: Column 3 | O1: Complete | P1: Complete | Q1: Complete | R1: Fail | S1: Fail | T1: Fail | V1: Complete | W1: Column 1 | X1: Column 2
A2: Level | B2: Total USED Booster | C2: Booster A used | D2: Booster B used | E2: Booster C used | F2: Booster A used | G2: Booster B used | H2: Booster C used | I2: %_used_booster | J2: %_A_used | K2: %_B_used | L2: %_C_used | M2: Total not USED Booster | N2: Total OWNED Booster | O2: Booster A owned | P2: Booster B owned | Q2: Booster C owned | R2: Booster A owned | S2: Booster B owned | T2: Booster C owned | U2: Total Rewarded | V2: %_A_owned | W2: %_B_owned | X2: %_C_owned
A3: 1 | B3: =C3+D3+E3+F3+G3+H3 -> 0 | C3: 0 | D3: 0 | E3: 0 | F3: 0 | G3: 0 | H3: 0 | I3: =(100*B3)/N3 -> #DIV/0! | J3: =((C3+F3)*100)/B3 -> #DIV/0! | K3: =((D3+G3)*100)/B3 -> #DIV/0! | L3: =((E3+H3)*100)/B3 -> #DIV/0! | N3: =O3+P3+Q3+R3+S3+T3 -> 0 | O3: 0 | P3: 0 | Q3: 0 | R3: 0 | S3: 0 | T3: 0 | U3: 3 | V3: =((O3+R3)*100)/N3 -> #DIV/0! | W3: =((P3+S3)*100)/N3 -> #DIV/0! | X3: =((Q3+T3)*100)/N3 -> #DIV/0!
A4: 2 | B4: =C4+D4+E4+F4+G4+H4 -> 0 | C4: 0 | D4: 0 | E4: 0 | F4: 0 | G4: 0 | H4: 0 | I4: =(100*B4)/N4 -> #DIV/0! | J4: =((C4+F4)*100)/B4 -> #DIV/0! | K4: =((D4+G4)*100)/B4 -> #DIV/0! | L4: =((E4+H4)*100)/B4 -> #DIV/0! | M4: =N4-B3 -> 0 | N4: =O4+P4+Q4+R4+S4+T4 -> 0 | O4: 0 | P4: 0 | Q4: 0 | R4: 0 | S4: 0 | T4: 0 | U4: 1 | V4: =((O4+R4)*100)/N4 -> #DIV/0! | W4: =((P4+S4)*100)/N4 -> #DIV/0! | X4: =((Q4+T4)*100)/N4 -> #DIV/0!
A5: 3 | B5: =C5+D5+E5+F5+G5+H5 -> 0 | C5: 0 | D5: 0 | E5: 0 | F5: 0 | G5: 0 | H5: 0 | I5: =(100*B5)/N5 -> #DIV/0! | J5: =((C5+F5)*100)/B5 -> #DIV/0! | K5: =((D5+G5)*100)/B5 -> #DIV/0! | L5: =((E5+H5)*100)/B5 -> #DIV/0! | M5: =N5-B4 -> 0 | N5: =O5+P5+Q5+R5+S5+T5 -> 0 | O5: 0 | P5: 0 | Q5: 0 | R5: 0 | S5: 0 | T5: 0 | U5: 3 | V5: =((O5+R5)*100)/N5 -> #DIV/0! | W5: =((P5+S5)*100)/N5 -> #DIV/0! | X5: =((Q5+T5)*100)/N5 -> #DIV/0!
A6: 4 | B6: =C6+D6+E6+F6+G6+H6 -> 0 | C6: 0 | D6: 0 | E6: 0 | F6: 0 | G6: 0 | H6: 0 | I6: =(100*B6)/N6 -> #DIV/0! | J6: =((C6+F6)*100)/B6 -> #DIV/0! | K6: =((D6+G6)*100)/B6 -> #DIV/0! | L6: =((E6+H6)*100)/B6 -> #DIV/0! | M6: =N6-B5 -> 0 | N6: =O6+P6+Q6+R6+S6+T6 -> 0 | O6: 0 | P6: 0 | Q6: 0 | R6: 0 | S6: 0 | T6: 0 | U6: 3 | V6: =((O6+R6)*100)/N6 -> #DIV/0! | W6: =((P6+S6)*100)/N6 -> #DIV/0! | X6: =((Q6+T6)*100)/N6 -> #DIV/0!
A7: 5 | B7: =C7+D7+E7+F7+G7+H7 -> 0 | C7: 0 | D7: 0 | E7: 0 | F7: 0 | G7: 0 | H7: 0 | I7: =(100*B7)/N7 -> #DIV/0! | J7: =((C7+F7)*100)/B7 -> #DIV/0! | K7: =((D7+G7)*100)/B7 -> #DIV/0! | L7: =((E7+H7)*100)/B7 -> #DIV/0! | M7: =N7-B6 -> 0 | N7: =O7+P7+Q7+R7+S7+T7 -> 0 | O7: 0 | P7: 0 | Q7: 0 | R7: 0 | S7: 0 | T7: 0 | U7: 5 | V7: =((O7+R7)*100)/N7 -> #DIV/0! | W7: =((P7+S7)*100)/N7 -> #DIV/0! | X7: =((Q7+T7)*100)/N7 -> #DIV/0!
A8: 6 | B8: =C8+D8+E8+F8+G8+H8 -> 0 | C8: 0 | D8: 0 | E8: 0 | F8: 0 | G8: 0 | H8: 0 | I8: =(100*B8)/N8 -> #DIV/0! | J8: =((C8+F8)*100)/B8 -> #DIV/0! | K8: =((D8+G8)*100)/B8 -> #DIV/0! | L8: =((E8+H8)*100)/B8 -> #DIV/0! | M8: =N8-B7 -> 0 | N8: =O8+P8+Q8+R8+S8+T8 -> 0 | O8: 0 | P8: 0 | Q8: 0 | R8: 0 | S8: 0 | T8: 0 | U8: 7 | V8: =((O8+R8)*100)/N8 -> #DIV/0! | W8: =((P8+S8)*100)/N8 -> #DIV/0! | X8: =((Q8+T8)*100)/N8 -> #DIV/0!
A9: 7 | B9: =C9+D9+E9+F9+G9+H9 -> 0 | C9: 0 | D9: 0 | E9: 0 | F9: 0 | G9: 0 | H9: 0 | I9: =(100*B9)/N9 -> #DIV/0! | J9: =((C9+F9)*100)/B9 -> #DIV/0! | K9: =((D9+G9)*100)/B9 -> #DIV/0! | L9: =((E9+H9)*100)/B9 -> #DIV/0! | M9: =N9-B8 -> 0 | N9: =O9+P9+Q9+R9+S9+T9 -> 0 | O9: 0 | P9: 0 | Q9: 0 | R9: 0 | S9: 0 | T9: 0 | U9: 3 | V9: =((O9+R9)*100)/N9 -> #DIV/0! | W9: =((P9+S9)*100)/N9 -> #DIV/0! | X9: =((Q9+T9)*100)/N9 -> #DIV/0!
A10: 8 | B10: =C10+D10+E10+F10+G10+H10 -> 4284.1304 | C10: 4283 | D10: 0 | E10: 0 | F10: 1.1303975 | G10: 0 | H10: 0 | I10: =(100*B10)/N10 -> 95.928704 | J10: =((C10+F10)*100)/B10 -> 100 | K10: =((D10+G10)*100)/B10 -> 0 | L10: =((E10+H10)*100)/B10 -> 0 | M10: =N10-B9 -> 4465.9525 | N10: =O10+P10+Q10+R10+S10+T10 -> 4465.9525 | O10: 4345 | P10: 0 | Q10: 0 | R10: 120.95253 | S10: 0 | T10: 0 | U10: 0 | V10: =((O10+R10)*100)/N10 -> 100 | W10: =((P10+S10)*100)/N10 -> 0 | X10: =((Q10+T10)*100)/N10 -> 0
A11: 9 | B11: =C11+D11+E11+F11+G11+H11 -> 98.52159 | C11: 94 | D11: 0 | E11: 0 | F11: 4.5215901 | G11: 0 | H11: 0 | I11: =(100*B11)/N11 -> 2.2220919 | J11: =((C11+F11)*100)/B11 -> 100 | K11: =((D11+G11)*100)/B11 -> 0 | L11: =((E11+H11)*100)/B11 -> 0 | M11: =N11-B10 -> 149.60109 | N11: =O11+P11+Q11+R11+S11+T11 -> 4433.7315 | O11: 4202 | P11: 0 | Q11: 0 | R11: 231.73149 | S11: 0 | T11: 0 | U11: 26 | V11: =((O11+R11)*100)/N11 -> 100 | W11: =((P11+S11)*100)/N11 -> 0 | X11: =((Q11+T11)*100)/N11 -> 0
A12: 10 | B12: =C12+D12+E12+F12+G12+H12 -> 58 | C12: 58 | D12: 0 | E12: 0 | F12: 0 | G12: 0 | H12: 0 | I12: =(100*B12)/N12 -> 1.4098808 | J12: =((C12+F12)*100)/B12 -> 100 | K12: =((D12+G12)*100)/B12 -> 0 | L12: =((E12+H12)*100)/B12 -> 0 | M12: =N12-B11 -> 4015.3014 | N12: =O12+P12+Q12+R12+S12+T12 -> 4113.823 | O12: 4020 | P12: 0 | Q12: 0 | R12: 93.822994 | S12: 0 | T12: 0 | U12: 8 | V12: =((O12+R12)*100)/N12 -> 100 | W12: =((P12+S12)*100)/N12 -> 0 | X12: =((Q12+T12)*100)/N12 -> 0
A13: 11 | B13: =C13+D13+E13+F13+G13+H13 -> 299.25908 | C13: 245 | D13: 0 | E13: 0 | F13: 54.259081 | G13: 0 | H13: 0 | I13: =(100*B13)/N13 -> 5.8276945 | J13: =((C13+F13)*100)/B13 -> 100 | K13: =((D13+G13)*100)/B13 -> 0 | L13: =((E13+H13)*100)/B13 -> 0 | M13: =N13-B12 -> 5077.1196 | N13: =O13+P13+Q13+R13+S13+T13 -> 5135.1196 | O13: 3487 | P13: 0 | Q13: 0 | R13: 1648.1196 | S13: 0 | T13: 0 | U13: 760 | V13: =((O13+R13)*100)/N13 -> 100 | W13: =((P13+S13)*100)/N13 -> 0 | X13: =((Q13+T13)*100)/N13 -> 0
A14: 12 | B14: =C14+D14+E14+F14+G14+H14 -> 3743.1304 | C14: 23 | D14: 3719 | E14: 0 | F14: 0 | G14: 1.1303975 | H14: 0 | I14: =(100*B14)/N14 -> 53.302475 | J14: =((C14+F14)*100)/B14 -> 0.61445896 | K14: =((D14+G14)*100)/B14 -> 99.385541 | L14: =((E14+H14)*100)/B14 -> 0 | M14: =N14-B13 -> 6723.1736 | N14: =O14+P14+Q14+R14+S14+T14 -> 7022.4327 | O14: 3307 | P14: 3651 | Q14: 0 | R14: 25.999143 | S14: 38.433516 | T14: 0 | U14: 479 | V14: =((O14+R14)*100)/N14 -> 47.462173 | W14: =((P14+S14)*100)/N14 -> 52.537827 | X14: =((Q14+T14)*100)/N14 -> 0
A15: 13 | B15: =C15+D15+E15+F15+G15+H15 -> 41 | C15: 9 | D15: 32 | E15: 0 | F15: 0 | G15: 0 | H15: 0 | I15: =(100*B15)/N15 -> 0.60470043 | J15: =((C15+F15)*100)/B15 -> 21.95122 | K15: =((D15+G15)*100)/B15 -> 78.04878 | L15: =((E15+H15)*100)/B15 -> 0 | M15: =N15-B14 -> 3037.0864 | N15: =O15+P15+Q15+R15+S15+T15 -> 6780.2168 | O15: 3226 | P15: 3535 | Q15: 0 | R15: 9.0431802 | S15: 10.173578 | T15: 0 | U15: 486 | V15: =((O15+R15)*100)/N15 -> 47.712976 | W15: =((P15+S15)*100)/N15 -> 52.287024 | X15: =((Q15+T15)*100)/N15 -> 0
... A202: 200 | B202: =C202+D202+E202+F202+G202+H202 -> 311.55877 | C202: 92 | D202: 11 | E202: 13 | F202: 132.25651 | G202: 35.042323 | H202: 28.259938 | I202: =(100*B202)/N202 -> 5.8726896 | J202: =((C202+F202)*100)/B202 -> 71.978879 | K202: =((D202+G202)*100)/B202 -> 14.778054 | L202: =((E202+H202)*100)/B202 -> 13.243067 | M202: =N202-B201 -> 5226.128 | N202: =O202+P202+Q202+R202+S202+T202 -> 5305.2143 | O202: 804 | P202: 349 | Q202: 102 | R202: 2702.7805 | S202: 1004.9234 | T202: 342.51045 | U202: 149 | V202: =((O202+R202)*100)/N202 -> 66.100637 | W202: =((P202+S202)*100)/N202 -> 25.520616 | X202: =((Q202+T202)*100)/N202 -> 8.3787463
A203: 201 | B203: =C203+D203+E203+F203+G203+H203 -> 0 | C203: 0 | D203: 0 | E203: 0 | F203: 0 | G203: 0 | H203: 0 | I203: =(100*B203)/N203 -> 0 | J203: =((C203+F203)*100)/B203 -> #DIV/0! | K203: =((D203+G203)*100)/B203 -> #DIV/0! | L203: =((E203+H203)*100)/B203 -> #DIV/0! | N203: =O203+P203+Q203+R203+S203+T203 -> 1283.2608 | O203: 841 | P203: 337 | Q203: 103 | R203: 2.260795 | S203: 0 | T203: 0 | U203: 79 | V203: =((O203+R203)*100)/N203 -> 65.712348 | W203: =((P203+S203)*100)/N203 -> 26.261225 | X203: =((Q203+T203)*100)/N203 -> 8.0264277
A204: 202 | B204: =C204+D204+E204+F204+G204+H204 -> 7 | C204: 7 | D204: 0 | E204: 0 | F204: 0 | G204: 0 | H204: 0 | I204: =(100*B204)/N204 -> 0.54415795 | J204: =((C204+F204)*100)/B204 -> 100 | K204: =((D204+G204)*100)/B204 -> 0 | L204: =((E204+H204)*100)/B204 -> 0 | N204: =O204+P204+Q204+R204+S204+T204 -> 1286.3912 | O204: 844 | P204: 338 | Q204: 101 | R204: 0 | S204: 1.1303975 | T204: 2.260795 | U204: 67 | V204: =((O204+R204)*100)/N204 -> 65.609902 | W204: =((P204+S204)*100)/N204 -> 26.362929 | X204: =((Q204+T204)*100)/N204 -> 8.027169
A205: 203 | B205: =C205+D205+E205+F205+G205+H205 -> 194.25737 | C205: 77 | D205: 4 | E205: 7 | F205: 93.822994 | G205: 7.9127827 | H205: 4.5215901 | I205: =(100*B205)/N205 -> 14.335732 | J205: =((C205+F205)*100)/B205 -> 87.93643 | K205: =((D205+G205)*100)/B205 -> 6.1324741 | L205: =((E205+H205)*100)/B205 -> 5.9310956 | N205: =O205+P205+Q205+R205+S205+T205 -> 1355.0572 | O205: 211 | P205: 165 | Q205: 77 | R205: 412.5951 | S205: 280.33859 | T205: 209.12354 | U205: 127 | V205: =((O205+R205)*100)/N205 -> 46.019835 | W205: =((P205+S205)*100)/N205 -> 32.864928 | X205: =((Q205+T205)*100)/N205 -> 21.115237
A206: 204 | B206: =C206+D206+E206+F206+G206+H206 -> 119.12868 | C206: 57 | D206: 3 | E206: 6 | F206: 40.694311 | G206: 5.6519876 | H206: 6.7823851 | I206: =(100*B206)/N206 -> 10.669419 | J206: =((C206+F206)*100)/B206 -> 82.007379 | K206: =((D206+G206)*100)/B206 -> 7.2627241 | L206: =((E206+H206)*100)/B206 -> 10.729897 | N206: =O206+P206+Q206+R206+S206+T206 -> 1116.5433 | O206: 206 | P206: 167 | Q206: 80 | R206: 289.38177 | S206: 233.99229 | T206: 140.16929 | U206: 103 | V206: =((O206+R206)*100)/N206 -> 44.367446 | W206: =((P206+S206)*100)/N206 -> 35.913723 | X206: =((Q206+T206)*100)/N206 -> 19.718831
A207: 205 | B207: =C207+D207+E207+F207+G207+H207 -> 18 | C207: 17 | D207: 1 | E207: 0 | F207: 0 | G207: 0 | H207: 0 | I207: =(100*B207)/N207 -> 3.6386107 | J207: =((C207+F207)*100)/B207 -> 94.444444 | K207: =((D207+G207)*100)/B207 -> 5.5555556 | L207: =((E207+H207)*100)/B207 -> 0 | N207: =O207+P207+Q207+R207+S207+T207 -> 494.69431 | O207: 204 | P207: 168 | Q207: 82 | R207: 29.390336 | S207: 7.9127827 | T207: 3.3911926 | U207: 77 | V207: =((O207+R207)*100)/N207 -> 47.178698 | W207: =((P207+S207)*100)/N207 -> 35.559896 | X207: =((Q207+T207)*100)/N207 -> 17.261406
A208: 206 | B208: =C208+D208+E208+F208+G208+H208 -> 94.955963 | C208: 70 | D208: 1 | E208: 7 | F208: 9.0431802 | G208: 3.3911926 | H208: 4.5215901 | I208: =(100*B208)/N208 -> 19.283136 | J208: =((C208+F208)*100)/B208 -> 83.241934 | K208: =((D208+G208)*100)/B208 -> 4.6244516 | L208: =((E208+H208)*100)/B208 -> 12.133614 | N208: =O208+P208+Q208+R208+S208+T208 -> 492.43009 | O208: 158 | P208: 126 | Q208: 66 | R208: 44.085503 | S208: 49.737491 | T208: 48.607093 | U208: 79 | V208: =((O208+R208)*100)/N208 -> 41.038415 | W208: =((P208+S208)*100)/N208 -> 35.687805 | X208: =((Q208+T208)*100)/N208 -> 23.27378
A209: 207 | B209: =C209+D209+E209+F209+G209+H209 -> 39.52159 | C209: 34 | D209: 0 | E209: 1 | F209: 3.3911926 | G209: 0 | H209: 1.1303975 | I209: =(100*B209)/N209 -> 5.4637746 | J209: =((C209+F209)*100)/B209 -> 94.609535 | K209: =((D209+G209)*100)/B209 -> 0 | L209: =((E209+H209)*100)/B209 -> 5.3904651 | N209: =O209+P209+Q209+R209+S209+T209 -> 723.33859 | O209: 195 | P209: 168 | Q209: 80 | R209: 143.56049 | S209: 76.867032 | T209: 59.911069 | U209: 111 | V209: =((O209+R209)*100)/N209 -> 46.805257 | W209: =((P209+S209)*100)/N209 -> 33.852339 | X209: =((Q209+T209)*100)/N209 -> 19.342404
A210: 208 | B210: =C210+D210+E210+F210+G210+H210 -> 171.04147 | C210: 94 | D210: 2 | E210: 14 | F210: 57.650274 | G210: 0 | H210: 3.3911926 | I210: =(100*B210)/N210 -> 15.401602 | J210: =((C210+F210)*100)/B210 -> 88.66287 | K210: =((D210+G210)*100)/B210 -> 1.1693071 | L210: =((E210+H210)*100)/B210 -> 10.167822 | N210: =O210+P210+Q210+R210+S210+T210 -> 1110.5433 | O210: 199 | P210: 167 | Q210: 81 | R210: 281.46898 | S210: 243.03547 | T210: 139.0389 | U210: 113 | V210: =((O210+R210)*100)/N210 -> 43.264316 | W210: =((P210+S210)*100)/N210 -> 36.922059 | X210: =((Q210+T210)*100)/N210 -> 19.813625
A211: 209 | B211: =C211+D211+E211+F211+G211+H211 -> 92.390336 | C211: 62 | D211: 0 | E211: 1 | F211: 29.390336 | G211: 0 | H211: 0 | I211: =(100*B211)/N211 -> 10.16316 | J211: =((C211+F211)*100)/B211 -> 98.917636 | K211: =((D211+G211)*100)/B211 -> 0 | L211: =((E211+H211)*100)/B211 -> 1.0823643 | N211: =O211+P211+Q211+R211+S211+T211 -> 909.07093 | O211: 176 | P211: 166 | Q211: 81 | R211: 203.47155 | S211: 153.73406 | T211: 128.86532 | U211: 102 | V211: =((O211+R211)*100)/N211 -> 41.742788 | W211: =((P211+S211)*100)/N211 -> 35.17152 | X211: =((Q211+T211)*100)/N211 -> 23.085692
A212: 210 | B212: =C212+D212+E212+F212+G212+H212 -> 461.33944 | C212: 35 | D212: 75 | E212: 97 | F212: 24.868746 | G212: 99.474982 | H212: 129.99572 | I212: =(100*B212)/N212 -> 54.340199 | J212: =((C212+F212)*100)/B212 -> 12.977157 | K212: =((D212+G212)*100)/B212 -> 37.819221 | L212: =((E212+H212)*100)/B212 -> 49.203622 | N212: =O212+P212+Q212+R212+S212+T212 -> 848.98372 | O212: 179 | P212: 125 | Q212: 51 | R212: 195.55877 | S212: 196.68917 | T212: 101.73578 | U212: 96 | V212: =((O212+R212)*100)/N212 -> 44.118487 | W212: =((P212+S212)*100)/N212 -> 37.891088 | X212: =((Q212+T212)*100)/N212 -> 17.990425
A213: 211 | B213: =C213+D213+E213+F213+G213+H213 -> 129.4767 | C213: 74 | D213: 3 | E213: 5 | F213: 42.955106 | G213: 3.3911926 | H213: 1.1303975 | I213: =(100*B213)/N213 -> 16.649066 | J213: =((C213+F213)*100)/B213 -> 90.329078 | K213: =((D213+G213)*100)/B213 -> 4.9361721 | L213: =((E213+H213)*100)/B213 -> 4.7347497 | N213: =O213+P213+Q213+R213+S213+T213 -> 777.68146 | O213: 165 | P213: 129 | Q213: 53 | R213: 229.4707 | S213: 128.86532 | T213: 72.345441 | U213: 111 | V213: =((O213+R213)*100)/N213 -> 50.723943 | W213: =((P213+S213)*100)/N213 -> 33.158219 | X213: =((Q213+T213)*100)/N213 -> 16.117839
A214: 212 | B214: =C214+D214+E214+F214+G214+H214 -> 108.82557 | C214: 70 | D214: 14 | E214: 9 | F214: 3.3911926 | G214: 9.0431802 | H214: 3.3911926 | I214: =(100*B214)/N214 -> 18.517592 | J214: =((C214+F214)*100)/B214 -> 67.439294 | K214: =((D214+G214)*100)/B214 -> 21.174418 | L214: =((E214+H214)*100)/B214 -> 11.386288 | N214: =O214+P214+Q214+R214+S214+T214 -> 587.68746 | O214: 162 | P214: 126 | Q214: 51 | R214: 102.86617 | S214: 93.822994 | T214: 51.998286 | U214: 106 | V214: =((O214+R214)*100)/N214 -> 45.069224 | W214: =((P214+S214)*100)/N214 -> 37.404745 | X214: =((Q214+T214)*100)/N214 -> 17.526031
... A402: 400 | B402: =C402+D402+E402+F402+G402+H402 -> 24.04318 | C402: 14 | D402: 0 | E402: 1 | F402: 9.0431802 | G402: 0 | H402: 0 | I402: =(100*B402)/N402 -> 8.8254496 | J402: =((C402+F402)*100)/B402 -> 95.840816 | K402: =((D402+G402)*100)/B402 -> 0 | L402: =((E402+H402)*100)/B402 -> 4.1591836 | N402: =O402+P402+Q402+R402+S402+T402 -> 272.43009 | O402: 45 | P402: 48 | Q402: 37 | R402: 46.346298 | S402: 53.128684 | T402: 42.955106 | U402: 34 | V402: =((O402+R402)*100)/N402 -> 33.53018 | W402: =((P402+S402)*100)/N402 -> 37.120967 | X402: =((Q402+T402)*100)/N402 -> 29.348853
A403: 401
A404: 402
A405: 403
A406: 404
A407: 405
A408: 406
A409: 407
A410: 408
A411: 409
A412: 410
A413: 411
...

Sheet IOS
A1: Segment | B1: Start | C1: Complete | D1: Fail | E1: Try again | L1: Complete | M1: LevelType | N1: =SUM(N3:N302) -> 2104.56 | O1: =(N1/C3)/300 -> 0.0087471322 | Q1: =AVERAGE(Q3:Q402) -> 0.35279772 | R1: =AVERAGE(R3:R402) -> 4.8241908 | S1: =AVERAGE(S3:S402) -> 6.6800291 | T1: =AVERAGE(T13:T302) -> 0.57606934 | U1: =AVERAGE(U3:U402) -> 1421.9663 | V1: =AVERAGE(V3:V402) -> 203527.15
A2: Level | B2: Active users | C2: Active users | D2: Active users | E2: Active users | F2: Complete rate | G2: Fail Rate | H2: Drop 1 | I2: Uncomplete | J2: Drop 2 | K2: % | L2: avarage_attempt | M2: LevelType | N2: Total $ | O2: ARPU | P2: %_used_booster | Q2: avg_used_booster | R2: avg_owned_booster | S2: Avg. Thinking Time | T2: Avg.Rewarded | U2: Avg,Coin | V2: coin owned
A3: 1 | B3: 825 | C3: 802 | D3: 12 | E3: 15 | F3: =(C3*100)/B3 -> 97.212121 | G3: =(D3*100)/B3 -> 1.4545455 | H3: =((B3-B4)/B3)*100 -> 2.9090909 | I3: =((B3-C3)/B3)*100 -> 2.7878788 | J3: =((C3-B4)/C3)*100 -> 0.12468828 | K3: =100-(((C3-C4)/C3)*100) -> 97.256858 | L3: 1.0024907 | M3: Normal | N3: 6.17 | O3: =N3/C3 -> 0.0076932668 | P3: =(Boosters_IOS!B3*100)/Boosters_IOS!N3 -> #DIV/0! | Q3: =Boosters_IOS!B3/(C3+D3) -> 0 | R3: =Boosters_IOS!N3/B3 -> 0 | S3: 0.0373599 | T3: 0 | U3: 396.88279 | V3: 280300
A4: 2 | B4: 801 | C4: 780 | D4: 5 | E4: 7 | F4: =(C4*100)/B4 -> 97.378277 | G4: =(D4*100)/B4 -> 0.62421973 | H4: =((B4-B5)/B4)*100 -> 2.7465668 | I4: =((B4-C4)/B4)*100 -> 2.6217228 | J4: =((C4-B5)/C4)*100 -> 0.12820513 | K4: =100-(((C3-C5)/C3)*100) -> 95.012469 | L4: 1.0025575 | M4: Normal | N4: 2.31 | O4: =N4/C4 -> 0.0029615385 | P4: =(Boosters_IOS!B4*100)/Boosters_IOS!N4 -> #DIV/0! | Q4: =Boosters_IOS!B4/(C4+D4) -> 0 | R4: =Boosters_IOS!N4/B4 -> 0 | S4: 0.0063938619 | T4: 0 | U4: 419.07692 | V4: 295580
A5: 3 | B5: 779 | C5: 762 | D5: 6 | E5: 7 | F5: =(C5*100)/B5 -> 97.817715 | G5: =(D5*100)/B5 -> 0.77021823 | H5: =((B5-B6)/B5)*100 -> 2.3106547 | I5: =((B5-C5)/B5)*100 -> 2.182285 | J5: =((C5-B6)/C5)*100 -> 0.1312336 | K5: =100-(((C3-C6)/C3)*100) -> 93.640898 | L5: 1.0039318 | M5: Normal | N5: 2.3 | O5: =N5/C5 -> 0.0030183727 | P5: =(Boosters_IOS!B5*100)/Boosters_IOS!N5 -> #DIV/0! | Q5: =Boosters_IOS!B5/(C5+D5) -> 0 | R5: =Boosters_IOS!N5/B5 -> 0 | S5: 3.7627785 | T5: 0 | U5: 441.49606 | V5: 310880
A6: 4 | B6: 761 | C6: 751 | D6: 9 | E6: 8 | F6: =(C6*100)/B6 -> 98.68594 | G6: =(D6*100)/B6 -> 1.1826544 | H6: =((B6-B7)/B6)*100 -> 0.91984231 | I6: =((B6-C6)/B6)*100 -> 1.3140604 | J6: =((C6-B7)/C6)*100 -> -0.39946738 | K6: =100-(((C3-C7)/C3)*100) -> 92.643392 | L6: 1.0119681 | M6: Normal | N6: 0 | O6: =N6/C6 -> 0 | P6: =(Boosters_IOS!B6*100)/Boosters_IOS!N6 -> #DIV/0! | Q6: =Boosters_IOS!B6/(C6+D6) -> 0 | R6: =Boosters_IOS!N6/B6 -> 0 | S6: 4.7207447 | T6: 0 | U6: 461.65113 | V6: 330980
A7: 5 | B7: 754 | C7: 743 | D7: 11 | E7: 12 | F7: =(C7*100)/B7 -> 98.541114 | G7: =(D7*100)/B7 -> 1.4588859 | H7: =((B7-B8)/B7)*100 -> 0.53050398 | I7: =((B7-C7)/B7)*100 -> 1.4588859 | J7: =((C7-B8)/C7)*100 -> -0.94212651 | K7: =100-(((C3-C8)/C3)*100) -> 92.144638 | L7: 1.0067204 | M7: Normal | N7: 0 | O7: =N7/C7 -> 0 | P7: =(Boosters_IOS!B7*100)/Boosters_IOS!N7 -> #DIV/0! | Q7: =Boosters_IOS!B7/(C7+D7) -> 0 | R7: =Boosters_IOS!N7/B7 -> 0 | S7: 4.0846774 | T7: 0.001345895 | U7: 481.2786 | V7: 344990
A8: 6 | B8: 750 | C8: 739 | D8: 28 | E8: 28 | F8: =(C8*100)/B8 -> 98.533333 | G8: =(D8*100)/B8 -> 3.7333333 | H8: =((B8-B9)/B8)*100 -> 0.93333333 | I8: =((B8-C8)/B8)*100 -> 1.4666667 | J8: =((C8-B9)/C8)*100 -> -0.54127199 | K8: =100-(((C3-C9)/C3)*100) -> 90.399002 | L8: 1.0148649 | M8: Normal | N8: 2.25 | O8: =N8/C8 -> 0.0030446549 | P8: =(Boosters_IOS!B8*100)/Boosters_IOS!N8 -> #DIV/0! | Q8: =Boosters_IOS!B8/(C8+D8) -> 0 | R8: =Boosters_IOS!N8/B8 -> 0 | S8: 4.0027027 | T8: 0 | U8: 501.27199 | V8: 357210
A9: 7 | B9: 743 | C9: 725 | D9: 20 | E9: 19 | F9: =(C9*100)/B9 -> 97.577389 | G9: =(D9*100)/B9 -> 2.69179 | H9: =((B9-B10)/B9)*100 -> 2.0188425 | I9: =((B9-C9)/B9)*100 -> 2.422611 | J9: =((C9-B10)/C9)*100 -> -0.4137931 | K9: =100-(((C3-C10)/C3)*100) -> 89.276808 | L9: 1.0041265 | M9: Normal | N9: 1.99 | O9: =N9/C9 -> 0.0027448276 | P9: =(Boosters_IOS!B9*100)/Boosters_IOS!N9 -> #DIV/0! | Q9: =Boosters_IOS!B9/(C9+D9) -> 0 | R9: =Boosters_IOS!N9/B9 -> 0 | S9: 4.4360385 | T9: 0 | U9: 523.53103 | V9: 369730
A10: 8 | B10: 728 | C10: 716 | D10: 3 | E10: 6 | F10: =(C10*100)/B10 -> 98.351648 | G10: =(D10*100)/B10 -> 0.41208791 | H10: =((B10-B11)/B10)*100 -> 1.510989 | I10: =((B10-C10)/B10)*100 -> 1.6483516 | J10: =((C10-B11)/C10)*100 -> -0.1396648 | K10: =100-(((C3-C11)/C3)*100) -> 88.154613 | L10: 1.0027855 | M10: Normal | N10: 0 | O10: =N10/C10 -> 0 | P10: =(Boosters_IOS!B10*100)/Boosters_IOS!N10 -> 98.825453 | Q10: =Boosters_IOS!B10/(C10+D10) -> 0.99721836 | R10: =Boosters_IOS!N10/B10 -> 0.99659559 | S10: 5.045961 | T10: 0.001396648 | U10: 542.6257 | V10: 383010
A11: 9 | B11: 717 | C11: 707 | D11: 40 | E11: 43 | F11: =(C11*100)/B11 -> 98.6053 | G11: =(D11*100)/B11 -> 5.5788006 | H11: =((B11-B12)/B11)*100 -> 2.6499303 | I11: =((B11-C11)/B11)*100 -> 1.3947001 | J11: =((C11-B12)/C11)*100 -> 1.2729844 | K11: =100-(((C3-C12)/C3)*100) -> 86.907731 | L11: 1.0409027 | M11: Normal | N11: 0 | O11: =N11/C11 -> 0 | P11: =(Boosters_IOS!B11*100)/Boosters_IOS!N11 -> 2.5821367 | Q11: =Boosters_IOS!B11/(C11+D11) -> 0.025435074 | R11: =Boosters_IOS!N11/B11 -> 1.0262548 | S11: 4.0042313 | T11: 0.0042432815 | U11: 564.38472 | V11: 397250
A12: 10 | B12: 698 | C12: 697 | D12: 16 | E12: 12 | F12: =(C12*100)/B12 -> 99.856734 | G12: =(D12*100)/B12 -> 2.2922636 | H12: =((B12-B13)/B12)*100 -> 1.7191977 | I12: =((B12-C12)/B12)*100 -> 0.14326648 | J12: =((C12-B13)/C12)*100 -> 1.5781923 | K12: =100-(((C3-C13)/C3)*100) -> 80.798005 | L12: 1.0229226 | M12: Normal | N12: 0 | O12: =N12/C12 -> 0 | P12: =(Boosters_IOS!B12*100)/Boosters_IOS!N12 -> 1.8924066 | Q12: =Boosters_IOS!B12/(C12+D12) -> 0.018232819 | R12: =Boosters_IOS!N12/B12 -> 0.9841776 | S12: 2.7363897 | T12: 0.0071736011 | U12: 590.67432 | V12: 411960
A13: 11 | B13: 686 | C13: 648 | D13: 205 | E13: 144 | F13: =(C13*100)/B13 -> 94.460641 | G13: =(D13*100)/B13 -> 29.883382 | H13: =((B13-B14)/B13)*100 -> 8.1632653 | I13: =((B13-C13)/B13)*100 -> 5.5393586 | J13: =((C13-B14)/C13)*100 -> 2.7777778 | K13: =100-(((C3-C14)/C3)*100) -> 78.179551 | L13: 1.1759259 | M13: Normal | N13: 9.6 | O13: =N13/C13 -> 0.014814815 | P13: =(Boosters_IOS!B13*100)/Boosters_IOS!N13 -> 5.2573312 | Q13: =Boosters_IOS!B13/(C13+D13) -> 0.055099648 | R13: =Boosters_IOS!N13/B13 -> 1.303192 | S13: 2.8935185 | T13: 0.13734568 | U13: 862.80864 | V13: 620340
A14: 12 | B14: 630 | C14: 627 | D14: 2 | E14: 3 | F14: =(C14*100)/B14 -> 99.52381 | G14: =(D14*100)/B14 -> 0.31746032 | H14: =((B14-B15)/B14)*100 -> 2.6984127 | I14: =((B14-C14)/B14)*100 -> 0.47619048 | J14: =((C14-B15)/C14)*100 -> 2.2328549 | K14: =100-(((C3-C15)/C3)*100) -> 76.433915 | L14: 1.0063796 | M14: Normal | N14: 0 | O14: =N14/C14 -> 0 | P14: =(Boosters_IOS!B14*100)/Boosters_IOS!N14 -> 55.487116 | Q14: =Boosters_IOS!B14/(C14+D14) -> 1.0397456 | R14: =Boosters_IOS!N14/B14 -> 1.8708762 | S14: 0.0031897927 | T14: 0.12280702 | U14: 983.38118 | V14: 666200
A15: 13 | B15: 613 | C15: 613 | D15: 0 | E15: 0 | F15: =(C15*100)/B15 -> 100 | G15: =(D15*100)/B15 -> 0 | H15: =((B15-B16)/B15)*100 -> 0 | I15: =((B15-C15)/B15)*100 -> 0 | J15: =((C15-B16)/C15)*100 -> 0 | K15: =100-(((C3-C16)/C3)*100) -> 74.189526 | L15: 1 | M15: Normal | N15: 14.41 | O15: =N15/C15 -> 0.023507341 | P15: =(Boosters_IOS!B15*100)/Boosters_IOS!N15 -> 0.43975374 | Q15: =Boosters_IOS!B15/(C15+D15) -> 0.0081566069 | R15: =Boosters_IOS!N15/B15 -> 1.8548124 | S15: 4.3050571 | T15: 0.1141925 | U15: 1019.8532 | V15: 685950
A16: 14 | B16: 613 | C16: 595 | D16: 206 | E16: 131 | F16: =(C16*100)/B16 -> 97.063622 | G16: =(D16*100)/B16 -> 33.60522 | H16: =((B16-B17)/B16)*100 -> 4.5676998 | I16: =((B16-C16)/B16)*100 -> 2.9363785 | J16: =((C16-B17)/C16)*100 -> 1.6806723 | K16: =100-(((C3-C17)/C3)*100) -> 72.693267 | L16: 1.2403361 | M16: Hard | N16: 4.72 | O16: =N16/C16 -> 0.0079327731 | P16: =(Boosters_IOS!B16*100)/Boosters_IOS!N16 -> 2.4970413 | Q16: =Boosters_IOS!B16/(C16+D16) -> 0.050317073 | R16: =Boosters_IOS!N16/B16 -> 2.6330656 | S16: 2.6487395 | T16: 0.12941176 | U16: 959.78151 | V16: 646560
A17: 15 | B17: 585 | C17: 583 | D17: 19 | E17: 15 | F17: =(C17*100)/B17 -> 99.65812 | G17: =(D17*100)/B17 -> 3.2478632 | H17: =((B17-B18)/B17)*100 -> 2.0512821 | I17: =((B17-C17)/B17)*100 -> 0.34188034 | J17: =((C17-B18)/C17)*100 -> 1.7152659 | K17: =100-(((C3-C18)/C3)*100) -> 70.074813 | L17: 1.0222985 | M17: Normal | N17: 0 | O17: =N17/C17 -> 0 | P17: =(Boosters_IOS!B17*100)/Boosters_IOS!N17 -> 0.45889919 | Q17: =Boosters_IOS!B17/(C17+D17) -> 0.0083056478 | R17: =Boosters_IOS!N17/B17 -> 1.8625024 | S17: 2.9176672 | T17: 0.10120069 | U17: 983.07033 | V17: 651180
A18: 16 | B18: 573 | C18: 562 | D18: 31 | E18: 28 | F18: =(C18*100)/B18 -> 98.080279 | G18: =(D18*100)/B18 -> 5.4101222 | H18: =((B18-B19)/B18)*100 -> 2.2687609 | I18: =((B18-C18)/B18)*100 -> 1.9197208 | J18: =((C18-B19)/C18)*100 -> 0.35587189 | K18: =100-(((C3-C19)/C3)*100) -> 69.201995 | L18: 1.019573 | M18: Normal | N18: 0 | O18: =N18/C18 -> 0 | P18: =(Boosters_IOS!B18*100)/Boosters_IOS!N18 -> 33.64929 | Q18: =Boosters_IOS!B18/(C18+D18) -> 0.97360397 | R18: =Boosters_IOS!N18/B18 -> 2.9943771 | S18: 0.18505338 | T18: 0.11032028 | U18: 1027.7758 | V18: 656630
A19: 17 | B19: 560 | C19: 555 | D19: 26 | E19: 20 | F19: =(C19*100)/B19 -> 99.107143 | G19: =(D19*100)/B19 -> 4.6428571 | H19: =((B19-B20)/B19)*100 -> 1.0714286 | I19: =((B19-C19)/B19)*100 -> 0.89285714 | J19: =((C19-B20)/C19)*100 -> 0.18018018 | K19: =100-(((C3-C20)/C3)*100) -> 68.952618 | L19: 1.0288288 | M19: Normal | N19: 0 | O19: =N19/C19 -> 0 | P19: =(Boosters_IOS!B19*100)/Boosters_IOS!N19 -> 0.43309322 | Q19: =Boosters_IOS!B19/(C19+D19) -> 0.012272629 | R19: =Boosters_IOS!N19/B19 -> 2.9399797 | S19: 3.9621622 | T19: 0.1045045 | U19: 1061.4775 | V19: 668830
A20: 18 | B20: 554 | C20: 553 | D20: 2 | E20: 4 | F20: =(C20*100)/B20 -> 99.819495 | G20: =(D20*100)/B20 -> 0.36101083 | H20: =((B20-B21)/B20)*100 -> 1.0830325 | I20: =((B20-C20)/B20)*100 -> 0.18050542 | J20: =((C20-B21)/C20)*100 -> 0.90415913 | K20: =100-(((C3-C21)/C3)*100) -> 67.830424 | L20: 1.0126582 | M20: Normal | N20: 0 | O20: =N20/C20 -> 0 | P20: =(Boosters_IOS!B20*100)/Boosters_IOS!N20 -> 0.25368117 | Q20: =Boosters_IOS!B20/(C20+D20) -> 0.0072072072 | R20: =Boosters_IOS!N20/B20 -> 2.8461776 | S20: 3.2622061 | T20: 0.11030741 | U20: 1097.2061 | V20: 681970
A21: 19 | B21: 548 | C21: 544 | D21: 5 | E21: 4 | F21: =(C21*100)/B21 -> 99.270073 | G21: =(D21*100)/B21 -> 0.91240876 | H21: =((B21-B22)/B21)*100 -> 2.3722628 | I21: =((B21-C21)/B21)*100 -> 0.72992701 | J21: =((C21-B22)/C21)*100 -> 1.6544118 | K21: =100-(((C3-C22)/C3)*100) -> 65.586035 | L21: 1.0091912 | M21: Normal | N21: 3.07 | O21: =N21/C21 -> 0.0056433824 | P21: =(Boosters_IOS!B21*100)/Boosters_IOS!N21 -> 0.38723809 | Q21: =Boosters_IOS!B21/(C21+D21) -> 0.010928962 | R21: =Boosters_IOS!N21/B21 -> 2.827435 | S21: 2.9007353 | T21: 0.20220588 | U21: 1131.5165 | V21: 713850
A22: 20 | B22: 535 | C22: 526 | D22: 43 | E22: 27 | F22: =(C22*100)/B22 -> 98.317757 | G22: =(D22*100)/B22 -> 8.0373832 | H22: =((B22-B23)/B22)*100 -> 1.8691589 | I22: =((B22-C22)/B22)*100 -> 1.682243 | J22: =((C22-B23)/C22)*100 -> 0.19011407 | K22: =100-(((C3-C23)/C3)*100) -> 64.713217 | L22: 1.0285171 | M22: Normal | N22: 17.17 | O22: =N22/C22 -> 0.032642586 | P22: =(Boosters_IOS!B22*100)/Boosters_IOS!N22 -> 5.5247967 | Q22: =Boosters_IOS!B22/(C22+D22) -> 0.15106496 | R22: =Boosters_IOS!N22/B22 -> 2.9080772 | S22: 3.8802281 | T22: 0.14448669 | U22: 1137.6521 | V22: 712820
A23: 21 | B23: 525 | C23: 519 | D23: 11 | E23: 9 | F23: =(C23*100)/B23 -> 98.857143 | G23: =(D23*100)/B23 -> 2.0952381 | H23: =((B23-B24)/B23)*100 -> 3.2380952 | I23: =((B23-C23)/B23)*100 -> 1.1428571 | J23: =((C23-B24)/C23)*100 -> 2.1194605 | K23: =100-(((C3-C24)/C3)*100) -> 63.341646 | L23: 1.0134875 | M23: Normal | N23: 4.6 | O23: =N23/C23 -> 0.0088631985 | P23: =(Boosters_IOS!B23*100)/Boosters_IOS!N23 -> 1.3105423 | Q23: =Boosters_IOS!B23/(C23+D23) -> 0.035849057 | R23: =Boosters_IOS!N23/B23 -> 2.7614886 | S23: 3.0789981 | T23: 0.31791908 | U23: 1249.9904 | V23: 761350
A24: 22 | B24: 508 | C24: 508 | D24: 6 | E24: 6 | F24: =(C24*100)/B24 -> 100 | G24: =(D24*100)/B24 -> 1.1811024 | H24: =((B24-B25)/B24)*100 -> 2.3622047 | I24: =((B24-C24)/B24)*100 -> 0 | J24: =((C24-B25)/C24)*100 -> 2.3622047 | K24: =100-(((C3-C25)/C3)*100) -> 59.850374 | L24: 1.0098425 | M24: Normal | N24: 0.94 | O24: =N24/C24 -> 0.0018503937 | P24: =(Boosters_IOS!B24*100)/Boosters_IOS!N24 -> 0.2818974 | Q24: =Boosters_IOS!B24/(C24+D24) -> 0.0077821012 | R24: =Boosters_IOS!N24/B24 -> 2.7932204 | S24: 2.8976378 | T24: 0.13976378 | U24: 1293.6024 | V24: 770940
A25: 23 | B25: 496 | C25: 480 | D25: 95 | E25: 70 | F25: =(C25*100)/B25 -> 96.774194 | G25: =(D25*100)/B25 -> 19.153226 | H25: =((B25-B26)/B25)*100 -> 4.233871 | I25: =((B25-C25)/B25)*100 -> 3.2258065 | J25: =((C25-B26)/C25)*100 -> 1.0416667 | K25: =100-(((C3-C26)/C3)*100) -> 58.72818 | L25: 1.1666667 | M25: Hard | N25: 2.21 | O25: =N25/C25 -> 0.0046041667 | P25: =(Boosters_IOS!B25*100)/Boosters_IOS!N25 -> 16.077708 | Q25: =Boosters_IOS!B25/(C25+D25) -> 0.45368477 | R25: =Boosters_IOS!N25/B25 -> 3.2712688 | S25: 5.0166667 | T25: 0.14166667 | U25: 1263.5312 | V25: 744710
A26: 24 | B26: 475 | C26: 471 | D26: 54 | E26: 35 | F26: =(C26*100)/B26 -> 99.157895 | G26: =(D26*100)/B26 -> 11.368421 | H26: =((B26-B27)/B26)*100 -> 3.3684211 | I26: =((B26-C26)/B26)*100 -> 0.84210526 | J26: =((C26-B27)/C26)*100 -> 2.5477707 | K26: =100-(((C3-C27)/C3)*100) -> 57.107232 | L26: 1.0488323 | M26: Normal | N26: 1.99 | O26: =N26/C26 -> 0.0042250531 | P26: =(Boosters_IOS!B26*100)/Boosters_IOS!N26 -> 11.712984 | Q26: =Boosters_IOS!B26/(C26+D26) -> 0.26591991 | R26: =Boosters_IOS!N26/B26 -> 2.5092792 | S26: 2.9915074 | T26: 0.17197452 | U26: 1342.2187 | V26: 764700
A27: 25 | B27: 459 | C27: 458 | D27: 2 | E27: 2 | F27: =(C27*100)/B27 -> 99.782135 | G27: =(D27*100)/B27 -> 0.43572985 | H27: =((B27-B28)/B27)*100 -> 0.21786492 | I27: =((B27-C27)/B27)*100 -> 0.21786492 | J27: =((C27-B28)/C27)*100 -> 0 | K27: =100-(((C3-C28)/C3)*100) -> 57.107232 | L27: 1.0065502 | M27: Normal | N27: 0 | O27: =N27/C27 -> 0 | P27: =(Boosters_IOS!B27*100)/Boosters_IOS!N27 -> 0.099524038 | Q27: =Boosters_IOS!B27/(C27+D27) -> 0.002173913 | R27: =Boosters_IOS!N27/B27 -> 2.1890684 | S27: 5.3165939 | T27: 0.11135371 | U27: 1368.3515 | V27: 773730
A28: 26 | B28: 458 | C28: 458 | D28: 0 | E28: 0 | F28: =(C28*100)/B28 -> 100 | G28: =(D28*100)/B28 -> 0 | H28: =((B28-B29)/B28)*100 -> 0.65502183 | I28: =((B28-C28)/B28)*100 -> 0 | J28: =((C28-B29)/C28)*100 -> 0.65502183 | K28: =100-(((C3-C29)/C3)*100) -> 55.735661 | L28: 1.0087336 | M28: Normal | N28: 0 | O28: =N28/C28 -> 0 | P28: =(Boosters_IOS!B28*100)/Boosters_IOS!N28 -> 0 | Q28: =Boosters_IOS!B28/(C28+D28) -> 0 | R28: =Boosters_IOS!N28/B28 -> 2.1812227 | S28: 2.0021834 | T28: 0.11790393 | U28: 1399.345 | V28: 786390
A29: 27 | B29: 455 | C29: 447 | D29: 114 | E29: 77 | F29: =(C29*100)/B29 -> 98.241758 | G29: =(D29*100)/B29 -> 25.054945 | H29: =((B29-B30)/B29)*100 -> 2.6373626 | I29: =((B29-C29)/B29)*100 -> 1.7582418 | J29: =((C29-B30)/C29)*100 -> 0.89485459 | K29: =100-(((C3-C30)/C3)*100) -> 55.361596 | L29: 1.1941964 | M29: Normal | N29: 5.01 | O29: =N29/C29 -> 0.011208054 | P29: =(Boosters_IOS!B29*100)/Boosters_IOS!N29 -> 0.63981615 | Q29: =Boosters_IOS!B29/(C29+D29) -> 0.014725125 | R29: =Boosters_IOS!N29/B29 -> 2.8376266 | S29: 2.3370536 | T29: 0.13199105 | U29: 1360.5593 | V29: 734560
A30: 28 | B30: 443 | C30: 444 | D30: 3 | E30: 3 | F30: =(C30*100)/B30 -> 100.22573 | G30: =(D30*100)/B30 -> 0.6772009 | H30: =((B30-B31)/B30)*100 -> -0.90293454 | I30: =((B30-C30)/B30)*100 -> -0.22573363 | J30: =((C30-B31)/C30)*100 -> -0.67567568 | K30: =100-(((C3-C31)/C3)*100) -> 55.610973 | L30: 1.009009 | M30: Normal | N30: 0 | O30: =N30/C30 -> 0 | P30: =(Boosters_IOS!B30*100)/Boosters_IOS!N30 -> 0.10158117 | Q30: =Boosters_IOS!B30/(C30+D30) -> 0.0022371365 | R30: =Boosters_IOS!N30/B30 -> 2.2221995 | S30: 2.4459459 | T30: 0.094594595 | U30: 1404.6396 | V30: 745250
A31: 29 | B31: 447 | C31: 446 | D31: 14 | E31: 9 | F31: =(C31*100)/B31 -> 99.776286 | G31: =(D31*100)/B31 -> 3.1319911 | H31: =((B31-B32)/B31)*100 -> 1.1185682 | I31: =((B31-C31)/B31)*100 -> 0.22371365 | J31: =((C31-B32)/C31)*100 -> 0.89686099 | K31: =100-(((C3-C32)/C3)*100) -> 54.862843 | L31: 1.029148 | M31: Normal | N31: 0.99 | O31: =N31/C31 -> 0.0022197309 | P31: =(Boosters_IOS!B31*100)/Boosters_IOS!N31 -> 0.097926627 | Q31: =Boosters_IOS!B31/(C31+D31) -> 0.002173913 | R31: =Boosters_IOS!N31/B31 -> 2.2845027 | S31: 3.4798206 | T31: 0.11434978 | U31: 1435.7063 | V31: 746090
A32: 30 | B32: 442 | C32: 440 | D32: 35 | E32: 23 | F32: =(C32*100)/B32 -> 99.547511 | G32: =(D32*100)/B32 -> 7.918552 | H32: =((B32-B33)/B32)*100 -> 0 | I32: =((B32-C32)/B32)*100 -> 0.45248869 | J32: =((C32-B33)/C32)*100 -> -0.45454545 | K32: =100-(((C3-C33)/C3)*100) -> 52.618454 | L32: 1.0477273 | M32: Normal | N32: 0 | O32: =N32/C32 -> 0 | P32: =(Boosters_IOS!B32*100)/Boosters_IOS!N32 -> 0.090451788 | Q32: =Boosters_IOS!B32/(C32+D32) -> 0.0021052632 | R32: =Boosters_IOS!N32/B32 -> 2.50127 | S32: 3.3272727 | T32: 0.1 | U32: 1458.2386 | V32: 753300
A33: 31 | B33: 442 | C33: 422 | D33: 162 | E33: 99 | F33: =(C33*100)/B33 -> 95.475113 | G33: =(D33*100)/B33 -> 36.651584 | H33: =((B33-B34)/B33)*100 -> 4.9773756 | I33: =((B33-C33)/B33)*100 -> 4.5248869 | J33: =((C33-B34)/C33)*100 -> 0.47393365 | K33: =100-(((C3-C34)/C3)*100) -> 51.496259 | L33: 1.2198582 | M33: Normal | N33: 0 | O33: =N33/C33 -> 0 | P33: =(Boosters_IOS!B33*100)/Boosters_IOS!N33 -> 0.3600552 | Q33: =Boosters_IOS!B33/(C33+D33) -> 0.010497256 | R33: =Boosters_IOS!N33/B33 -> 3.8520976 | S33: 3.3026005 | T33: 0.13981043 | U33: 1350.3081 | V33: 665840
A34: 32 | B34: 420 | C34: 413 | D34: 63 | E34: 49 | F34: =(C34*100)/B34 -> 98.333333 | G34: =(D34*100)/B34 -> 15 | H34: =((B34-B35)/B34)*100 -> -1.6666667 | I34: =((B34-C34)/B34)*100 -> 1.6666667 | J34: =((C34-B35)/C34)*100 -> -3.3898305 | K34: =100-(((C3-C35)/C3)*100) -> 52.618454 | L34: 1.0895884 | M34: Normal | N34: 0 | O34: =N34/C34 -> 0 | P34: =(Boosters_IOS!B34*100)/Boosters_IOS!N34 -> 2.0178769 | Q34: =Boosters_IOS!B34/(C34+D34) -> 0.046218487 | R34: =Boosters_IOS!N34/B34 -> 2.5958448 | S34: 4.1791768 | T34: 0.12590799 | U34: 1388.5593 | V34: 653035
A35: 33 | B35: 427 | C35: 422 | D35: 58 | E35: 43 | F35: =(C35*100)/B35 -> 98.82904 | G35: =(D35*100)/B35 -> 13.583138 | H35: =((B35-B36)/B35)*100 -> 0.46838407 | I35: =((B35-C35)/B35)*100 -> 1.1709602 | J35: =((C35-B36)/C35)*100 -> -0.71090047 | K35: =100-(((C3-C36)/C3)*100) -> 52.992519 | L35: 1.0758294 | M35: Normal | N35: 9.4 | O35: =N35/C35 -> 0.022274882 | P35: =(Boosters_IOS!B35*100)/Boosters_IOS!N35 -> 0.26347083 | Q35: =Boosters_IOS!B35/(C35+D35) -> 0.00625 | R35: =Boosters_IOS!N35/B35 -> 2.6666182 | S35: 3.2345972 | T35: 0.11848341 | U35: 1372.2393 | V35: 639730
A36: 34 | B36: 425 | C36: 425 | D36: 12 | E36: 10 | F36: =(C36*100)/B36 -> 100 | G36: =(D36*100)/B36 -> 2.8235294 | H36: =((B36-B37)/B36)*100 -> 0 | I36: =((B36-C36)/B36)*100 -> 0 | J36: =((C36-B37)/C36)*100 -> 0 | K36: =100-(((C3-C37)/C3)*100) -> 52.119701 | L36: 1.0258824 | M36: Normal | N36: 0.99 | O36: =N36/C36 -> 0.0023294118 | P36: =(Boosters_IOS!B36*100)/Boosters_IOS!N36 -> 0.19913433 | Q36: =Boosters_IOS!B36/(C36+D36) -> 0.004576659 | R36: =Boosters_IOS!N36/B36 -> 2.3631698 | S36: 3.0564706 | T36: 0.12470588 | U36: 1422.2471 | V36: 645380
