Workbook

Sheet ARPU
U2: Level | V2: ARPU AND | W2: ARPU IOS
U3: 1 | V3: =And!O3 | W3: =IOS!O3
U4: 2 | V4: =And!O4 | W4: =IOS!O4
U5: 3 | V5: =And!O5 | W5: =IOS!O5
U6: 4 | V6: =And!O6 | W6: =IOS!O6
U7: 5 | V7: =And!O7 | W7: =IOS!O7
U8: 6 | V8: =And!O8 | W8: =IOS!O8
U9: 7 | V9: =And!O9 | W9: =IOS!O9
U10: 8 | V10: =And!O10 | W10: =IOS!O10
U11: 9 | V11: =And!O11 | W11: =IOS!O11
U12: 10 | V12: =And!O12 | W12: =IOS!O12
U13: 11 | V13: =And!O13 | W13: =IOS!O13
U14: 12 | V14: =And!O14 | W14: =IOS!O14
... U523: 521 | V523: =And!O523 | W523: =IOS!O523
U524: 522
U525: 523
U526: 524
U527: 525
U528: 526
U529: 527
U530: 528
U531: 529
U532: 530
U533: 531
U534: 532
U535: 533
... U1215: 1213

Sheet Av.Rw
U2: Level | V2: AND_Avg Rwr | W2: IOS_Avg Rwr
U3: 1 | V3: =And!T3 | W3: =IOS!T3
U4: 2 | V4: =And!T4 | W4: =IOS!T4
U5: 3 | V5: =And!T5 | W5: =IOS!T5
U6: 4 | V6: =And!T6 | W6: =IOS!T6
U7: 5 | V7: =And!T7 | W7: =IOS!T7
U8: 6 | V8: =And!T8 | W8: =IOS!T8
U9: 7 | V9: =And!T9 | W9: =IOS!T9
U10: 8 | V10: =And!T10 | W10: =IOS!T10
U11: 9 | V11: =And!T11 | W11: =IOS!T11
U12: 10 | V12: =And!T12 | W12: =IOS!T12
U13: 11 | V13: =And!T13 | W13: =IOS!T13
U14: 12 | V14: =And!T14 | W14: =IOS!T14
... U402: 400 | V402: =And!T402 | W402: =IOS!T402
U403: 401 | V403: #REF! | W403: #REF!
U404: 402 | V404: #REF! | W404: #REF!
U405: 403 | V405: #REF! | W405: #REF!
U406: 404 | V406: #REF! | W406: #REF!
U407: 405 | V407: #REF! | W407: #REF!
U408: 406 | V408: #REF! | W408: #REF!
U409: 407 | V409: #REF! | W409: #REF!
U410: 408 | V410: #REF! | W410: #REF!
U411: 409 | V411: #REF! | W411: #REF!
U412: 410 | V412: #REF! | W412: #REF!
U413: 411 | V413: #REF! | W413: #REF!
U414: 412 | V414: #REF! | W414: #REF!
... U502: 500 | V502: #REF! | W502: #REF!
U503: 501
U504: 502
U505: 503
U506: 504
U507: 505
U508: 506
U509: 507
U510: 508
U511: 509
U512: 510
U513: 511
U514: 512
... U1215: 1213

Sheet And
A1: Segment | B1: Start | C1: Complete | D1: Fail | E1: Try again | L1: Complete | M1: LevelType | N1: =SUM(N3:N302) | O1: =(N1/C3)/300 | Q1: =AVERAGE(Q3:Q202) | R1: =AVERAGE(R3:R202) | S1: =AVERAGE(S3:S402) | T1: =AVERAGE(T13:T202) | V1: =AVERAGE(V3:V402)
A2: Level | B2: Active users | C2: Active users | D2: Active users | E2: Active users | F2: Complete rate | G2: Fail Rate | H2: Drop 1 | I2: Uncomplete | J2: Drop 2 | K2: % | L2: avarage_attempt | M2: LevelType | N2: Total $ | O2: ARPU | P2: %_used_booster | Q2: avg_used_booster | R2: avg_owned_booster | S2: Avg. Thinking Time | T2: Avg.Rewarded | U2: Owned Coin | V2: Avg. Coin
A3: 1 | B3: 9456 | C3: 9167 | D3: 240 | E3: 317 | F3: =(C3*100)/B3 | G3: =(D3*100)/B3 | H3: =((B3-B4)/B3)*100 | I3: =((B3-C3)/B3)*100 | J3: =((C3-B4)/C3)*100 | K3: =100-(((C3-C4)/C3)*100) | L3: 1.0078608 | M3: Normal | N3: 32.05 | O3: =N3/C3 | P3: =(Boosters_And!B3*100)/Boosters_And!N3 | Q3: =Boosters_And!B3/(C3+D3) | R3: =Boosters_And!N3/B3 | S3: 0.10555867 | T3: 13 | U3: 2167426.9 | V3: =U3/B3
A4: 2 | B4: 9172 | C4: 9092 | D4: 108 | E4: 137 | F4: =(C4*100)/B4 | G4: =(D4*100)/B4 | H4: =((B4-B5)/B4)*100 | I4: =((B4-C4)/B4)*100 | J4: =((C4-B5)/C4)*100 | K4: =100-(((C3-C5)/C3)*100) | L4: 1.0028321 | M4: Normal | N4: 8.37 | O4: =N4/C4 | P4: =(Boosters_And!B4*100)/Boosters_And!N4 | Q4: =Boosters_And!B4/(C4+D4) | R4: =Boosters_And!N4/B4 | S4: 0.021240442 | T4: 5 | U4: 2344808.8 | V4: =U4/B4
A5: 3 | B5: 9077 | C5: 8986 | D5: 113 | E5: 162 | F5: =(C5*100)/B5 | G5: =(D5*100)/B5 | H5: =((B5-B6)/B5)*100 | I5: =((B5-C5)/B5)*100 | J5: =((C5-B6)/C5)*100 | K5: =100-(((C3-C6)/C3)*100) | L5: 1.0022923 | M5: Normal | N5: 21.9 | O5: =N5/C5 | P5: =(Boosters_And!B5*100)/Boosters_And!N5 | Q5: =Boosters_And!B5/(C5+D5) | R5: =Boosters_And!N5/B5 | S5: 5.9183381 | T5: 10 | U5: 3345596.2 | V5: =U5/B5
A6: 4 | B6: 8994 | C6: 8912 | D6: 126 | E6: 188 | F6: =(C6*100)/B6 | G6: =(D6*100)/B6 | H6: =((B6-B7)/B6)*100 | I6: =((B6-C6)/B6)*100 | J6: =((C6-B7)/C6)*100 | K6: =100-(((C3-C7)/C3)*100) | L6: 1.0028902 | M6: Normal | N6: 5.97 | O6: =N6/C6 | P6: =(Boosters_And!B6*100)/Boosters_And!N6 | Q6: =Boosters_And!B6/(C6+D6) | R6: =Boosters_And!N6/B6 | S6: 5.5867052 | T6: 0 | U6: 6622659.1 | V6: =U6/B6
A7: 5 | B7: 8919 | C7: 8801 | D7: 165 | E7: 250 | F7: =(C7*100)/B7 | G7: =(D7*100)/B7 | H7: =((B7-B8)/B7)*100 | I7: =((B7-C7)/B7)*100 | J7: =((C7-B8)/C7)*100 | K7: =100-(((C3-C8)/C3)*100) | L7: 1.0038034 | M7: Normal | N7: 5.92 | O7: =N7/C7 | P7: =(Boosters_And!B7*100)/Boosters_And!N7 | Q7: =Boosters_And!B7/(C7+D7) | R7: =Boosters_And!N7/B7 | S7: 6.6100059 | T7: 3 | U7: 6786009.2 | V7: =U7/B7
A8: 6 | B8: 8801 | C8: 8631 | D8: 263 | E8: 371 | F8: =(C8*100)/B8 | G8: =(D8*100)/B8 | H8: =((B8-B9)/B8)*100 | I8: =((B8-C8)/B8)*100 | J8: =((C8-B9)/C8)*100 | K8: =100-(((C3-C9)/C3)*100) | L8: 1.0053667 | M8: Normal | N8: 12.26 | O8: =N8/C8 | P8: =(Boosters_And!B8*100)/Boosters_And!N8 | Q8: =Boosters_And!B8/(C8+D8) | R8: =Boosters_And!N8/B8 | S8: 5.7182469 | T8: 13 | U8: 6929575.8 | V8: =U8/B8
A9: 7 | B9: 8643 | C9: 8499 | D9: 199 | E9: 322 | F9: =(C9*100)/B9 | G9: =(D9*100)/B9 | H9: =((B9-B10)/B9)*100 | I9: =((B9-C9)/B9)*100 | J9: =((C9-B10)/C9)*100 | K9: =100-(((C3-C10)/C3)*100) | L9: 1.0015142 | M9: Normal | N9: 5.97 | O9: =N9/C9 | P9: =(Boosters_And!B9*100)/Boosters_And!N9 | Q9: =Boosters_And!B9/(C9+D9) | R9: =Boosters_And!N9/B9 | S9: 6.2350091 | T9: 0 | U9: 7076856.6 | V9: =U9/B9
A10: 8 | B10: 8512 | C10: 8419 | D10: 150 | E10: 248 | F10: =(C10*100)/B10 | G10: =(D10*100)/B10 | H10: =((B10-B11)/B10)*100 | I10: =((B10-C10)/B10)*100 | J10: =((C10-B11)/C10)*100 | K10: =100-(((C3-C11)/C3)*100) | L10: 1.0015291 | M10: Normal | N10: 7.96 | O10: =N10/C10 | P10: =(Boosters_And!B10*100)/Boosters_And!N10 | Q10: =Boosters_And!B10/(C10+D10) | R10: =Boosters_And!N10/B10 | S10: 5.1373089 | T10: 0 | U10: 7230121.5 | V10: =U10/B10
A11: 9 | B11: 8432 | C11: 8308 | D11: 317 | E11: 413 | F11: =(C11*100)/B11 | G11: =(D11*100)/B11 | H11: =((B11-B12)/B11)*100 | I11: =((B11-C11)/B11)*100 | J11: =((C11-B12)/C11)*100 | K11: =100-(((C3-C12)/C3)*100) | L11: 1.0207559 | M11: Normal | N11: 8.97 | O11: =N11/C11 | P11: =(Boosters_And!B11*100)/Boosters_And!N11 | Q11: =Boosters_And!B11/(C11+D11) | R11: =Boosters_And!N11/B11 | S11: 5.7218092 | T11: 28 | U11: 7373868.7 | V11: =U11/B11
A12: 10 | B12: 8122 | C12: 8086 | D12: 168 | E12: 165 | F12: =(C12*100)/B12 | G12: =(D12*100)/B12 | H12: =((B12-B13)/B12)*100 | I12: =((B12-C12)/B12)*100 | J12: =((C12-B13)/C12)*100 | K12: =100-(((C3-C13)/C3)*100) | L12: 1.0130532 | M12: Normal | N12: 53.6 | O12: =N12/C12 | P12: =(Boosters_And!B12*100)/Boosters_And!N12 | Q12: =Boosters_And!B12/(C12+D12) | R12: =Boosters_And!N12/B12 | S12: 4.1171601 | T12: 36 | U12: 7484084.2 | V12: =U12/B12
A13: 11 | B13: 7790 | C13: 7475 | D13: 1767 | E13: 1548 | F13: =(C13*100)/B13 | G13: =(D13*100)/B13 | H13: =((B13-B14)/B13)*100 | I13: =((B13-C13)/B13)*100 | J13: =((C13-B14)/C13)*100 | K13: =100-(((C3-C14)/C3)*100) | L13: 1.1620131 | M13: Normal | N13: 73.53 | O13: =N13/C13 | P13: =(Boosters_And!B13*100)/Boosters_And!N13 | Q13: =Boosters_And!B13/(C13+D13) | R13: =Boosters_And!N13/B13 | S13: 4.1802827 | T13: 1470 | U13: 9972124.3 | V13: =U13/B13
A14: 12 | B14: 7109 | C14: 7091 | D14: 64 | E14: 88 | F14: =(C14*100)/B14 | G14: =(D14*100)/B14 | H14: =((B14-B15)/B14)*100 | I14: =((B14-C14)/B14)*100 | J14: =((C14-B15)/C14)*100 | K14: =100-(((C3-C15)/C3)*100) | L14: 1.001454 | M14: Normal | N14: 194.35 | O14: =N14/C14 | P14: =(Boosters_And!B14*100)/Boosters_And!N14 | Q14: =Boosters_And!B14/(C14+D14) | R14: =Boosters_And!N14/B14 | S14: 0.026899309 | T14: 867 | U14: 10434292 | V14: =U14/B14
A15: 13 | B15: 6957 | C15: 6944 | D15: 23 | E15: 23 | F15: =(C15*100)/B15 | G15: =(D15*100)/B15 | H15: =((B15-B16)/B15)*100 | I15: =((B15-C15)/B15)*100 | J15: =((C15-B16)/C15)*100 | K15: =100-(((C3-C16)/C3)*100) | L15: 1.0022272 | M15: Normal | N15: 38.84 | O15: =N15/C15 | P15: =(Boosters_And!B15*100)/Boosters_And!N15 | Q15: =Boosters_And!B15/(C15+D15) | R15: =Boosters_And!N15/B15 | S15: 5.3919822 | T15: 818 | U15: 10662487 | V15: =U15/B15
A16: 14 | B16: 6871 | C16: 6681 | D16: 1826 | E16: 1501 | F16: =(C16*100)/B16 | G16: =(D16*100)/B16 | H16: =((B16-B17)/B16)*100 | I16: =((B16-C16)/B16)*100 | J16: =((C16-B17)/C16)*100 | K16: =100-(((C3-C17)/C3)*100) | L16: 1.2510605 | M16: Hard | N16: 41.37 | O16: =N16/C16 | P16: =(Boosters_And!B16*100)/Boosters_And!N16 | Q16: =Boosters_And!B16/(C16+D16) | R16: =Boosters_And!N16/B16 | S16: 3.377555 | T16: 1119 | U16: 6180068.6 | V16: =U16/B16
A17: 15 | B17: 6608 | C17: 6585 | D17: 183 | E17: 183 | F17: =(C17*100)/B17 | G17: =(D17*100)/B17 | H17: =((B17-B18)/B17)*100 | I17: =((B17-C17)/B17)*100 | J17: =((C17-B18)/C17)*100 | K17: =100-(((C3-C18)/C3)*100) | L17: 1.0199687 | M17: Normal | N17: 9.98 | O17: =N17/C17 | P17: =(Boosters_And!B17*100)/Boosters_And!N17 | Q17: =Boosters_And!B17/(C17+D17) | R17: =Boosters_And!N17/B17 | S17: 4.6589663 | T17: 751 | U17: 6337898.9 | V17: =U17/B17
A18: 16 | B18: 6456 | C18: 6420 | D18: 330 | E18: 284 | F18: =(C18*100)/B18 | G18: =(D18*100)/B18 | H18: =((B18-B19)/B18)*100 | I18: =((B18-C18)/B18)*100 | J18: =((C18-B19)/C18)*100 | K18: =100-(((C3-C19)/C3)*100) | L18: 1.0108434 | M18: Normal | N18: 27.42 | O18: =N18/C18 | P18: =(Boosters_And!B18*100)/Boosters_And!N18 | Q18: =Boosters_And!B18/(C18+D18) | R18: =Boosters_And!N18/B18 | S18: 0.19959839 | T18: 704 | U18: 6743088.9 | V18: =U18/B18
A19: 17 | B19: 6299 | C19: 6276 | D19: 206 | E19: 178 | F19: =(C19*100)/B19 | G19: =(D19*100)/B19 | H19: =((B19-B20)/B19)*100 | I19: =((B19-C19)/B19)*100 | J19: =((C19-B20)/C19)*100 | K19: =100-(((C3-C20)/C3)*100) | L19: 1.0176664 | M19: Normal | N19: 26.94 | O19: =N19/C19 | P19: =(Boosters_And!B19*100)/Boosters_And!N19 | Q19: =Boosters_And!B19/(C19+D19) | R19: =Boosters_And!N19/B19 | S19: 5.0928513 | T19: 735 | U19: 6796507.2 | V19: =U19/B19
A20: 18 | B20: 6196 | C20: 6193 | D20: 21 | E20: 18 | F20: =(C20*100)/B20 | G20: =(D20*100)/B20 | H20: =((B20-B21)/B20)*100 | I20: =((B20-C20)/B20)*100 | J20: =((C20-B21)/C20)*100 | K20: =100-(((C3-C21)/C3)*100) | L20: 1.0029142 | M20: Normal | N20: 15.96 | O20: =N20/C20 | P20: =(Boosters_And!B20*100)/Boosters_And!N20 | Q20: =Boosters_And!B20/(C20+D20) | R20: =Boosters_And!N20/B20 | S20: 4.4983347 | T20: 694 | U20: 6921915.1 | V20: =U20/B20
A21: 19 | B21: 6080 | C21: 6072 | D21: 36 | E21: 34 | F21: =(C21*100)/B21 | G21: =(D21*100)/B21 | H21: =((B21-B22)/B21)*100 | I21: =((B21-C21)/B21)*100 | J21: =((C21-B22)/C21)*100 | K21: =100-(((C3-C22)/C3)*100) | L21: 1.0016985 | M21: Normal | N21: 85.5 | O21: =N21/C21 | P21: =(Boosters_And!B21*100)/Boosters_And!N21 | Q21: =Boosters_And!B21/(C21+D21) | R21: =Boosters_And!N21/B21 | S21: 4.2929936 | T21: 1352 | U21: 7128056.7 | V21: =U21/B21
A22: 20 | B22: 5961 | C22: 5917 | D22: 433 | E22: 291 | F22: =(C22*100)/B22 | G22: =(D22*100)/B22 | H22: =((B22-B23)/B22)*100 | I22: =((B22-C22)/B22)*100 | J22: =((C22-B23)/C22)*100 | K22: =100-(((C3-C23)/C3)*100) | L22: 1.021796 | M22: Normal | N22: 35.94 | O22: =N22/C22 | P22: =(Boosters_And!B22*100)/Boosters_And!N22 | Q22: =Boosters_And!B22/(C22+D22) | R22: =Boosters_And!N22/B22 | S22: 4.7179599 | T22: 874 | U22: 6973734.3 | V22: =U22/B22
A23: 21 | B23: 5726 | C23: 5703 | D23: 85 | E23: 101 | F23: =(C23*100)/B23 | G23: =(D23*100)/B23 | H23: =((B23-B24)/B23)*100 | I23: =((B23-C23)/B23)*100 | J23: =((C23-B24)/C23)*100 | K23: =100-(((C3-C24)/C3)*100) | L23: 1.0013569 | M23: Normal | N23: 52.43 | O23: =N23/C23 | P23: =(Boosters_And!B23*100)/Boosters_And!N23 | Q23: =Boosters_And!B23/(C23+D23) | R23: =Boosters_And!N23/B23 | S23: 4.2555405 | T23: 1638 | U23: 7602940.6 | V23: =U23/B23
A24: 22 | B24: 5551 | C24: 5538 | D24: 34 | E24: 39 | F24: =(C24*100)/B24 | G24: =(D24*100)/B24 | H24: =((B24-B25)/B24)*100 | I24: =((B24-C24)/B24)*100 | J24: =((C24-B25)/C24)*100 | K24: =100-(((C3-C25)/C3)*100) | L24: 1.0013973 | M24: Normal | N24: 69.14 | O24: =N24/C24 | P24: =(Boosters_And!B24*100)/Boosters_And!N24 | Q24: =Boosters_And!B24/(C24+D24) | R24: =Boosters_And!N24/B24 | S24: 4.6725664 | T24: 859 | U24: 7709313 | V24: =U24/B24
A25: 23 | B25: 5476 | C25: 5386 | D25: 1045 | E25: 601 | F25: =(C25*100)/B25 | G25: =(D25*100)/B25 | H25: =((B25-B26)/B25)*100 | I25: =((B25-C25)/B25)*100 | J25: =((C25-B26)/C25)*100 | K25: =100-(((C3-C26)/C3)*100) | L25: 1.1187739 | M25: Hard | N25: 46.48 | O25: =N25/C25 | P25: =(Boosters_And!B25*100)/Boosters_And!N25 | Q25: =Boosters_And!B25/(C25+D25) | R25: =Boosters_And!N25/B25 | S25: 6.2978927 | T25: 934 | U25: 7012852.7 | V25: =U25/B25
A26: 24 | B26: 5347 | C26: 5306 | D26: 526 | E26: 356 | F26: =(C26*100)/B26 | G26: =(D26*100)/B26 | H26: =((B26-B27)/B26)*100 | I26: =((B26-C26)/B26)*100 | J26: =((C26-B27)/C26)*100 | K26: =100-(((C3-C27)/C3)*100) | L26: 1.0461838 | M26: Normal | N26: 36.95 | O26: =N26/C26 | P26: =(Boosters_And!B26*100)/Boosters_And!N26 | Q26: =Boosters_And!B26/(C26+D26) | R26: =Boosters_And!N26/B26 | S26: 5.6451142 | T26: 846 | U26: 7254873 | V26: =U26/B26
A27: 25 | B27: 5239 | C27: 5236 | D27: 8 | E27: 10 | F27: =(C27*100)/B27 | G27: =(D27*100)/B27 | H27: =((B27-B28)/B27)*100 | I27: =((B27-C27)/B27)*100 | J27: =((C27-B28)/C27)*100 | K27: =100-(((C3-C28)/C3)*100) | L27: 1.0019695 | M27: Normal | N27: 0.99 | O27: =N27/C27 | P27: =(Boosters_And!B27*100)/Boosters_And!N27 | Q27: =Boosters_And!B27/(C27+D27) | R27: =Boosters_And!N27/B27 | S27: 7.4805515 | T27: 725 | U27: 7429752.8 | V27: =U27/B27
A28: 26 | B28: 5159 | C28: 5159 | D28: 0 | E28: 0 | F28: =(C28*100)/B28 | G28: =(D28*100)/B28 | H28: =((B28-B29)/B28)*100 | I28: =((B28-C28)/B28)*100 | J28: =((C28-B29)/C28)*100 | K28: =100-(((C3-C29)/C3)*100) | L28: 1.001999 | M28: Normal | N28: 5.97 | O28: =N28/C28 | P28: =(Boosters_And!B28*100)/Boosters_And!N28 | Q28: =Boosters_And!B28/(C28+D28) | R28: =Boosters_And!N28/B28 | S28: 2.3713143 | T28: 642 | U28: 7535970.4 | V28: =U28/B28
A29: 27 | B29: 5094 | C29: 5027 | D29: 1174 | E29: 578 | F29: =(C29*100)/B29 | G29: =(D29*100)/B29 | H29: =((B29-B30)/B29)*100 | I29: =((B29-C29)/B29)*100 | J29: =((C29-B30)/C29)*100 | K29: =100-(((C3-C30)/C3)*100) | L29: 1.1430769 | M29: Normal | N29: 39.44 | O29: =N29/C29 | P29: =(Boosters_And!B29*100)/Boosters_And!N29 | Q29: =Boosters_And!B29/(C29+D29) | R29: =Boosters_And!N29/B29 | S29: 2.8789744 | T29: 782 | U29: 6876766.2 | V29: =U29/B29
A30: 28 | B30: 4914 | C30: 4898 | D30: 21 | E30: 21 | F30: =(C30*100)/B30 | G30: =(D30*100)/B30 | H30: =((B30-B31)/B30)*100 | I30: =((B30-C30)/B30)*100 | J30: =((C30-B31)/C30)*100 | K30: =100-(((C3-C31)/C3)*100) | L30: 1.0021064 | M30: Normal | N30: 26.83 | O30: =N30/C30 | P30: =(Boosters_And!B30*100)/Boosters_And!N30 | Q30: =Boosters_And!B30/(C30+D30) | R30: =Boosters_And!N30/B30 | S30: 3.9383886 | T30: 624 | U30: 7016412.2 | V30: =U30/B30
A31: 29 | B31: 4865 | C31: 4849 | D31: 137 | E31: 111 | F31: =(C31*100)/B31 | G31: =(D31*100)/B31 | H31: =((B31-B32)/B31)*100 | I31: =((B31-C31)/B31)*100 | J31: =((C31-B32)/C31)*100 | K31: =100-(((C3-C32)/C3)*100) | L31: 1.0143617 | M31: Normal | N31: 5.97 | O31: =N31/C31 | P31: =(Boosters_And!B31*100)/Boosters_And!N31 | Q31: =Boosters_And!B31/(C31+D31) | R31: =Boosters_And!N31/B31 | S31: 3.7031915 | T31: 616 | U31: 7104677.5 | V31: =U31/B31
A32: 30 | B32: 4798 | C32: 4780 | D32: 273 | E32: 165 | F32: =(C32*100)/B32 | G32: =(D32*100)/B32 | H32: =((B32-B33)/B32)*100 | I32: =((B32-C32)/B32)*100 | J32: =((C32-B33)/C32)*100 | K32: =100-(((C3-C33)/C3)*100) | L32: 1.0307609 | M32: Normal | N32: 20.46 | O32: =N32/C32 | P32: =(Boosters_And!B32*100)/Boosters_And!N32 | Q32: =Boosters_And!B32/(C32+D32) | R32: =Boosters_And!N32/B32 | S32: 3.7415003 | T32: 660 | U32: 7082211.4 | V32: =U32/B32
A33: 31 | B33: 4702 | C33: 4614 | D33: 1426 | E33: 818 | F33: =(C33*100)/B33 | G33: =(D33*100)/B33 | H33: =((B33-B34)/B33)*100 | I33: =((B33-C33)/B33)*100 | J33: =((C33-B34)/C33)*100 | L33: 1.2207937 | M33: Normal | N33: 51.84 | O33: =N33/C33 | P33: =(Boosters_And!B33*100)/Boosters_And!N33 | Q33: =Boosters_And!B33/(C33+D33) | R33: =Boosters_And!N33/B33 | S33: 4.3761878 | T33: 843 | U33: 6240634.3 | V33: =U33/B33
A34: 32 | B34: 4514 | C34: 4442 | D34: 596 | E34: 369 | F34: =(C34*100)/B34 | G34: =(D34*100)/B34 | H34: =((B34-B35)/B34)*100 | I34: =((B34-C34)/B34)*100 | J34: =((C34-B35)/C34)*100 | L34: 1.0650407 | M34: Normal | N34: 44.52 | O34: =N34/C34 | P34: =(Boosters_And!B34*100)/Boosters_And!N34 | Q34: =Boosters_And!B34/(C34+D34) | R34: =Boosters_And!N34/B34 | S34: 5.0638792 | T34: 704 | U34: 6057526.3 | V34: =U34/B34
A35: 33 | B35: 4362 | C35: 4349 | D35: 459 | E35: 284 | F35: =(C35*100)/B35 | G35: =(D35*100)/B35 | H35: =((B35-B36)/B35)*100 | I35: =((B35-C35)/B35)*100 | J35: =((C35-B36)/C35)*100 | L35: 1.0539739 | M35: Normal | N35: 25.54 | O35: =N35/C35 | P35: =(Boosters_And!B35*100)/Boosters_And!N35 | Q35: =Boosters_And!B35/(C35+D35) | R35: =Boosters_And!N35/B35 | S35: 4.0747331 | T35: 627 | U35: 5895527.7 | V35: =U35/B35
A36: 34 | B36: 4274 | C36: 4248 | D36: 113 | E36: 83 | F36: =(C36*100)/B36 | G36: =(D36*100)/B36 | H36: =((B36-B37)/B36)*100 | I36: =((B36-C36)/B36)*100 | J36: =((C36-B37)/C36)*100 | L36: 1.010929 | M36: Normal | N36: 19.7 | O36: =N36/C36 | P36: =(Boosters_And!B36*100)/Boosters_And!N36 | Q36: =Boosters_And!B36/(C36+D36) | R36: =Boosters_And!N36/B36 | S36: 4.1621129 | T36: 606 | U36: 6023050.7 | V36: =U36/B36
A37: 35 | B37: 4230 | C37: 4202 | D37: 653 | E37: 364 | F37: =(C37*100)/B37 | G37: =(D37*100)/B37 | H37: =((B37-B38)/B37)*100 | I37: =((B37-C37)/B37)*100 | J37: =((C37-B38)/C37)*100 | L37: 1.0816452 | M37: Normal | N37: 15.16 | O37: =N37/C37 | P37: =(Boosters_And!B37*100)/Boosters_And!N37 | Q37: =Boosters_And!B37/(C37+D37) | R37: =Boosters_And!N37/B37 | S37: 4.626151 | T37: 653 | U37: 5821281.1 | V37: =U37/B37
A38: 36 | B38: 4127 | C38: 4130 | D38: 15 | E38: 21 | F38: =(C38*100)/B38 | G38: =(D38*100)/B38 | H38: =((B38-B39)/B38)*100 | I38: =((B38-C38)/B38)*100 | J38: =((C38-B39)/C38)*100 | L38: 1.0012492 | M38: Normal | N38: 28.88 | O38: =N38/C38 | P38: =(Boosters_And!B38*100)/Boosters_And!N38 | Q38: =Boosters_And!B38/(C38+D38) | R38: =Boosters_And!N38/B38 | S38: 7.1486571 | T38: 580 | U38: 5874480.2 | V38: =U38/B38
A39: 37 | B39: 4091 | C39: 4088 | D39: 10 | E39: 15 | F39: =(C39*100)/B39 | G39: =(D39*100)/B39 | H39: =((B39-B40)/B39)*100 | I39: =((B39-C39)/B39)*100 | J39: =((C39-B40)/C39)*100 | L39: 1.0012618 | M39: Normal | N39: 24.21 | O39: =N39/C39 | P39: =(Boosters_And!B39*100)/Boosters_And!N39 | Q39: =Boosters_And!B39/(C39+D39) | R39: =Boosters_And!N39/B39 | S39: 2.8012618 | T39: 485 | U39: 5972198.8 | V39: =U39/B39
A40: 38 | B40: 4052 | C40: 4044 | D40: 13 | E40: 21 | F40: =(C40*100)/B40 | G40: =(D40*100)/B40 | H40: =((B40-B41)/B40)*100 | I40: =((B40-C40)/B40)*100 | J40: =((C40-B41)/C40)*100 | L40: 1.0012755 | M40: Normal | N40: 60.93 | O40: =N40/C40 | P40: =(Boosters_And!B40*100)/Boosters_And!N40 | Q40: =Boosters_And!B40/(C40+D40) | R40: =Boosters_And!N40/B40 | S40: 3.1779337 | T40: 537 | U40: 6157022.1 | V40: =U40/B40
...

Sheet Boosters_And
A1: Segment | C1: Complete | D1: Complete | E1: Complete | F1: Fail | G1: Fail | H1: Fail | J1: Complete | K1: Column 1 | L1: Column 2 | M1: Column 3 | O1: Complete | P1: Complete | Q1: Complete | R1: Fail | S1: Fail | T1: Fail | V1: Complete | W1: Column 1 | X1: Column 2
A2: Level | B2: Total USED Booster | C2: Booster A used | D2: Booster B used | E2: Booster C used | F2: Booster A used | G2: Booster B used | H2: Booster C used | I2: %_used_booster | J2: %_A_used | K2: %_B_used | L2: %_C_used | M2: Total not USED Booster | N2: Total OWNED Booster | O2: Booster A owned | P2: Booster B owned | Q2: Booster C owned | R2: Booster A owned | S2: Booster B owned | T2: Booster C owned | U2: Total Rewarded | V2: %_A_owned | W2: %_B_owned | X2: %_C_owned
A3: 1 | B3: =C3+D3+E3+F3+G3+H3 | C3: 0 | D3: 0 | E3: 0 | F3: 0 | G3: 0 | H3: 0 | I3: =(100*B3)/N3 | J3: =((C3+F3)*100)/B3 | K3: =((D3+G3)*100)/B3 | L3: =((E3+H3)*100)/B3 | N3: =O3+P3+Q3+R3+S3+T3 | O3: 0 | P3: 0 | Q3: 0 | R3: 0 | S3: 0 | T3: 0 | U3: 13 | V3: =((O3+R3)*100)/N3 | W3: =((P3+S3)*100)/N3 | X3: =((Q3+T3)*100)/N3
A4: 2 | B4: =C4+D4+E4+F4+G4+H4 | C4: 0 | D4: 0 | E4: 0 | F4: 0 | G4: 0 | H4: 0 | I4: =(100*B4)/N4 | J4: =((C4+F4)*100)/B4 | K4: =((D4+G4)*100)/B4 | L4: =((E4+H4)*100)/B4 | M4: =N4-B3 | N4: =O4+P4+Q4+R4+S4+T4 | O4: 0 | P4: 0 | Q4: 0 | R4: 0 | S4: 0 | T4: 0 | U4: 5 | V4: =((O4+R4)*100)/N4 | W4: =((P4+S4)*100)/N4 | X4: =((Q4+T4)*100)/N4
A5: 3 | B5: =C5+D5+E5+F5+G5+H5 | C5: 0 | D5: 0 | E5: 0 | F5: 0 | G5: 0 | H5: 0 | I5: =(100*B5)/N5 | J5: =((C5+F5)*100)/B5 | K5: =((D5+G5)*100)/B5 | L5: =((E5+H5)*100)/B5 | M5: =N5-B4 | N5: =O5+P5+Q5+R5+S5+T5 | O5: 0 | P5: 0 | Q5: 0 | R5: 0 | S5: 0 | T5: 0 | U5: 10 | V5: =((O5+R5)*100)/N5 | W5: =((P5+S5)*100)/N5 | X5: =((Q5+T5)*100)/N5
A6: 4 | B6: =C6+D6+E6+F6+G6+H6 | C6: 0 | D6: 0 | E6: 0 | F6: 0 | G6: 0 | H6: 0 | I6: =(100*B6)/N6 | J6: =((C6+F6)*100)/B6 | K6: =((D6+G6)*100)/B6 | L6: =((E6+H6)*100)/B6 | M6: =N6-B5 | N6: =O6+P6+Q6+R6+S6+T6 | O6: 0 | P6: 0 | Q6: 0 | R6: 0 | S6: 0 | T6: 0 | U6: 0 | V6: =((O6+R6)*100)/N6 | W6: =((P6+S6)*100)/N6 | X6: =((Q6+T6)*100)/N6
A7: 5 | B7: =C7+D7+E7+F7+G7+H7 | C7: 0 | D7: 0 | E7: 0 | F7: 0 | G7: 0 | H7: 0 | I7: =(100*B7)/N7 | J7: =((C7+F7)*100)/B7 | K7: =((D7+G7)*100)/B7 | L7: =((E7+H7)*100)/B7 | M7: =N7-B6 | N7: =O7+P7+Q7+R7+S7+T7 | O7: 0 | P7: 0 | Q7: 0 | R7: 0 | S7: 0 | T7: 0 | U7: 3 | V7: =((O7+R7)*100)/N7 | W7: =((P7+S7)*100)/N7 | X7: =((Q7+T7)*100)/N7
A8: 6 | B8: =C8+D8+E8+F8+G8+H8 | C8: 0 | D8: 0 | E8: 0 | F8: 0 | G8: 0 | H8: 0 | I8: =(100*B8)/N8 | J8: =((C8+F8)*100)/B8 | K8: =((D8+G8)*100)/B8 | L8: =((E8+H8)*100)/B8 | M8: =N8-B7 | N8: =O8+P8+Q8+R8+S8+T8 | O8: 0 | P8: 0 | Q8: 0 | R8: 0 | S8: 0 | T8: 0 | U8: 13 | V8: =((O8+R8)*100)/N8 | W8: =((P8+S8)*100)/N8 | X8: =((Q8+T8)*100)/N8
A9: 7 | B9: =C9+D9+E9+F9+G9+H9 | C9: 0 | D9: 0 | E9: 0 | F9: 0 | G9: 0 | H9: 0 | I9: =(100*B9)/N9 | J9: =((C9+F9)*100)/B9 | K9: =((D9+G9)*100)/B9 | L9: =((E9+H9)*100)/B9 | M9: =N9-B8 | N9: =O9+P9+Q9+R9+S9+T9 | O9: 0 | P9: 0 | Q9: 0 | R9: 0 | S9: 0 | T9: 0 | U9: 0 | V9: =((O9+R9)*100)/N9 | W9: =((P9+S9)*100)/N9 | X9: =((Q9+T9)*100)/N9
A10: 8 | B10: =C10+D10+E10+F10+G10+H10 | C10: 8331.2972 | D10: 0 | E10: 0 | F10: 5.158698 | G10: 0 | H10: 0 | I10: =(100*B10)/N10 | J10: =((C10+F10)*100)/B10 | K10: =((D10+G10)*100)/B10 | L10: =((E10+H10)*100)/B10 | M10: =N10-B9 | N10: =O10+P10+Q10+R10+S10+T10 | O10: 8470.5821 | P10: 0 | Q10: 0 | R10: 255.35555 | S10: 0 | T10: 0 | U10: 0 | V10: =((O10+R10)*100)/N10 | W10: =((P10+S10)*100)/N10 | X10: =((Q10+T10)*100)/N10
A11: 9 | B11: =C11+D11+E11+F11+G11+H11 | C11: 152.18159 | D11: 0 | E11: 0 | F11: 0 | G11: 0 | H11: 0 | I11: =(100*B11)/N11 | J11: =((C11+F11)*100)/B11 | K11: =((D11+G11)*100)/B11 | L11: =((E11+H11)*100)/B11 | M11: =N11-B10 | N11: =O11+P11+Q11+R11+S11+T11 | O11: 8207.4885 | P11: 0 | Q11: 0 | R11: 353.37081 | S11: 0 | T11: 0 | U11: 28 | V11: =((O11+R11)*100)/N11 | W11: =((P11+S11)*100)/N11 | X11: =((Q11+T11)*100)/N11
A12: 10 | B12: =C12+D12+E12+F12+G12+H12 | C12: 100.59461 | D12: 0 | E12: 0 | F12: 5.158698 | G12: 0 | H12: 0 | I12: =(100*B12)/N12 | J12: =((C12+F12)*100)/B12 | K12: =((D12+G12)*100)/B12 | L12: =((E12+H12)*100)/B12 | M12: =N12-B11 | N12: =O12+P12+Q12+R12+S12+T12 | O12: 7900.5459 | P12: 0 | Q12: 0 | R12: 159.91964 | S12: 0 | T12: 0 | U12: 36 | V12: =((O12+R12)*100)/N12 | W12: =((P12+S12)*100)/N12 | X12: =((Q12+T12)*100)/N12
A13: 11 | B13: =C13+D13+E13+F13+G13+H13 | C13: 417.85453 | D13: 0 | E13: 0 | F13: 85.118516 | G13: 0 | H13: 0 | I13: =(100*B13)/N13 | J13: =((C13+F13)*100)/B13 | K13: =((D13+G13)*100)/B13 | L13: =((E13+H13)*100)/B13 | M13: =N13-B12 | N13: =O13+P13+Q13+R13+S13+T13 | O13: 6876.5444 | P13: 0 | Q13: 0 | R13: 2605.1425 | S13: 0 | T13: 0 | U13: 1470 | V13: =((O13+R13)*100)/N13 | W13: =((P13+S13)*100)/N13 | X13: =((Q13+T13)*100)/N13
A14: 12 | B14: =C14+D14+E14+F14+G14+H14 | C14: 36.110886 | D14: 7173.1695 | E14: 0 | F14: 0 | G14: 5.158698 | H14: 0 | I14: =(100*B14)/N14 | J14: =((C14+F14)*100)/B14 | K14: =((D14+G14)*100)/B14 | L14: =((E14+H14)*100)/B14 | M14: =N14-B13 | N14: =O14+P14+Q14+R14+S14+T14 | O14: 6497.3801 | P14: 7039.0434 | Q14: 0 | R14: 59.325027 | S14: 103.17396 | T14: 0 | U14: 867 | V14: =((O14+R14)*100)/N14 | W14: =((P14+S14)*100)/N14 | X14: =((Q14+T14)*100)/N14
A15: 13 | B15: =C15+D15+E15+F15+G15+H15 | C15: 18.055443 | D15: 46.428282 | E15: 0 | F15: 0 | G15: 0 | H15: 0 | I15: =(100*B15)/N15 | J15: =((C15+F15)*100)/B15 | K15: =((D15+G15)*100)/B15 | L15: =((E15+H15)*100)/B15 | M15: =N15-B14 | N15: =O15+P15+Q15+R15+S15+T15 | O15: 6352.9365 | P15: 6853.3302 | Q15: 0 | R15: 20.634792 | S15: 20.634792 | T15: 0 | U15: 818 | V15: =((O15+R15)*100)/N15 | W15: =((P15+S15)*100)/N15 | X15: =((Q15+T15)*100)/N15
... A202: 200 | B202: =C202+D202+E202+F202+G202+H202 | C202: 157.34029 | D202: 12.896745 | E202: 30.952188 | F202: 177.97508 | G202: 18.055443 | H202: 28.372839 | I202: =(100*B202)/N202 | J202: =((C202+F202)*100)/B202 | K202: =((D202+G202)*100)/B202 | L202: =((E202+H202)*100)/B202 | M202: =N202-B201 | N202: =O202+P202+Q202+R202+S202+T202 | O202: 358.52951 | P202: 216.66531 | Q202: 64.483725 | R202: 737.69381 | S202: 363.68821 | T202: 105.75331 | U202: 232 | V202: =((O202+R202)*100)/N202 | W202: =((P202+S202)*100)/N202 | X202: =((Q202+T202)*100)/N202
A203: 201 | B203: =C203+D203+E203+F203+G203+H203 | C203: 0 | D203: 0 | E203: 0 | F203: 0 | G203: 0 | H203: 0 | I203: =(100*B203)/N203 | J203: =((C203+F203)*100)/B203 | K203: =((D203+G203)*100)/B203 | L203: =((E203+H203)*100)/B203 | N203: =O203+P203+Q203+R203+S203+T203 | O203: 417.85453 | P203: 221.82401 | Q203: 79.959818 | R203: 0 | S203: 0 | T203: 0 | U203: 129 | V203: =((O203+R203)*100)/N203 | W203: =((P203+S203)*100)/N203 | X203: =((Q203+T203)*100)/N203
A204: 202 | B204: =C204+D204+E204+F204+G204+H204 | C204: 15.476094 | D204: 0 | E204: 0 | F204: 0 | G204: 0 | H204: 0 | I204: =(100*B204)/N204 | J204: =((C204+F204)*100)/B204 | K204: =((D204+G204)*100)/B204 | L204: =((E204+H204)*100)/B204 | N204: =O204+P204+Q204+R204+S204+T204 | O204: 407.53714 | P204: 221.82401 | Q204: 79.959818 | R204: 12.896745 | S204: 0 | T204: 0 | U204: 124 | V204: =((O204+R204)*100)/N204 | W204: =((P204+S204)*100)/N204 | X204: =((Q204+T204)*100)/N204
A205: 203 | B205: =C205+D205+E205+F205+G205+H205 | C205: 175.39573 | D205: 5.158698 | E205: 20.634792 | F205: 123.80875 | G205: 7.7380469 | H205: 18.055443 | I205: =(100*B205)/N205 | J205: =((C205+F205)*100)/B205 | K205: =((D205+G205)*100)/B205 | L205: =((E205+H205)*100)/B205 | N205: =O205+P205+Q205+R205+S205+T205 | O205: 343.05341 | P205: 216.66531 | Q205: 64.483725 | R205: 484.91761 | S205: 252.7762 | T205: 49.007631 | U205: 201 | V205: =((O205+R205)*100)/N205 | W205: =((P205+S205)*100)/N205 | X205: =((Q205+T205)*100)/N205
A206: 204 | B206: =C206+D206+E206+F206+G206+H206 | C206: 95.435912 | D206: 5.158698 | E206: 20.634792 | F206: 56.745678 | G206: 15.476094 | H206: 20.634792 | I206: =(100*B206)/N206 | J206: =((C206+F206)*100)/B206 | K206: =((D206+G206)*100)/B206 | L206: =((E206+H206)*100)/B206 | N206: =O206+P206+Q206+R206+S206+T206 | O206: 348.21211 | P206: 219.24466 | Q206: 56.745678 | R206: 366.26756 | S206: 136.7055 | T206: 69.642422 | U206: 175 | V206: =((O206+R206)*100)/N206 | W206: =((P206+S206)*100)/N206 | X206: =((Q206+T206)*100)/N206
A207: 205 | B207: =C207+D207+E207+F207+G207+H207 | C207: 46.428282 | D207: 0 | E207: 0 | F207: 0 | G207: 0 | H207: 0 | I207: =(100*B207)/N207 | J207: =((C207+F207)*100)/B207 | K207: =((D207+G207)*100)/B207 | L207: =((E207+H207)*100)/B207 | N207: =O207+P207+Q207+R207+S207+T207 | O207: 340.47407 | P207: 232.14141 | Q207: 59.325027 | R207: 15.476094 | S207: 2.579349 | T207: 0 | U207: 116 | V207: =((O207+R207)*100)/N207 | W207: =((P207+S207)*100)/N207 | X207: =((Q207+T207)*100)/N207
A208: 206 | B208: =C208+D208+E208+F208+G208+H208 | C208: 123.80875 | D208: 10.317396 | E208: 5.158698 | F208: 18.055443 | G208: 10.317396 | H208: 10.317396 | I208: =(100*B208)/N208 | J208: =((C208+F208)*100)/B208 | K208: =((D208+G208)*100)/B208 | L208: =((E208+H208)*100)/B208 | N208: =O208+P208+Q208+R208+S208+T208 | O208: 348.21211 | P208: 221.82401 | Q208: 59.325027 | R208: 82.539167 | S208: 56.745678 | T208: 10.317396 | U208: 142 | V208: =((O208+R208)*100)/N208 | W208: =((P208+S208)*100)/N208 | X208: =((Q208+T208)*100)/N208
A209: 207 | B209: =C209+D209+E209+F209+G209+H209 | C209: 79.959818 | D209: 2.579349 | E209: 0 | F209: 10.317396 | G209: 2.579349 | H209: 0 | I209: =(100*B209)/N209 | J209: =((C209+F209)*100)/B209 | K209: =((D209+G209)*100)/B209 | L209: =((E209+H209)*100)/B209 | N209: =O209+P209+Q209+R209+S209+T209 | O209: 358.52951 | P209: 226.98271 | Q209: 64.483725 | R209: 206.34792 | S209: 108.33266 | T209: 23.214141 | U209: 188 | V209: =((O209+R209)*100)/N209 | W209: =((P209+S209)*100)/N209 | X209: =((Q209+T209)*100)/N209
A210: 208 | B210: =C210+D210+E210+F210+G210+H210 | C210: 193.45117 | D210: 7.7380469 | E210: 51.58698 | F210: 110.91201 | G210: 7.7380469 | H210: 12.896745 | I210: =(100*B210)/N210 | J210: =((C210+F210)*100)/B210 | K210: =((D210+G210)*100)/B210 | L210: =((E210+H210)*100)/B210 | N210: =O210+P210+Q210+R210+S210+T210 | O210: 350.79146 | P210: 226.98271 | Q210: 51.58698 | R210: 335.31537 | S210: 172.81638 | T210: 33.531537 | U210: 193 | V210: =((O210+R210)*100)/N210 | W210: =((P210+S210)*100)/N210 | X210: =((Q210+T210)*100)/N210
A211: 209 | B211: =C211+D211+E211+F211+G211+H211 | C211: 108.33266 | D211: 2.579349 | E211: 10.317396 | F211: 33.531537 | G211: 0 | H211: 5.158698 | I211: =(100*B211)/N211 | J211: =((C211+F211)*100)/B211 | K211: =((D211+G211)*100)/B211 | L211: =((E211+H211)*100)/B211 | N211: =O211+P211+Q211+R211+S211+T211 | O211: 332.73602 | P211: 224.40336 | Q211: 49.007631 | R211: 281.14904 | S211: 154.76094 | T211: 30.952188 | U211: 183 | V211: =((O211+R211)*100)/N211 | W211: =((P211+S211)*100)/N211 | X211: =((Q211+T211)*100)/N211
A212: 210 | B212: =C212+D212+E212+F212+G212+H212 | C212: 87.697865 | D212: 118.65005 | E212: 157.34029 | F212: 30.952188 | G212: 103.17396 | H212: 108.33266 | I212: =(100*B212)/N212 | J212: =((C212+F212)*100)/B212 | K212: =((D212+G212)*100)/B212 | L212: =((E212+H212)*100)/B212 | N212: =O212+P212+Q212+R212+S212+T212 | O212: 283.72839 | P212: 149.60224 | Q212: 18.055443 | R212: 348.21211 | S212: 74.80112 | T212: 7.7380469 | U212: 168 | V212: =((O212+R212)*100)/N212 | W212: =((P212+S212)*100)/N212 | X212: =((Q212+T212)*100)/N212
A213: 211 | B213: =C213+D213+E213+F213+G213+H213 | C213: 177.97508 | D213: 2.579349 | E213: 15.476094 | F213: 67.063073 | G213: 0 | H213: 2.579349 | I213: =(100*B213)/N213 | J213: =((C213+F213)*100)/B213 | K213: =((D213+G213)*100)/B213 | L213: =((E213+H213)*100)/B213 | N213: =O213+P213+Q213+R213+S213+T213 | O213: 270.83164 | P213: 162.49899 | Q213: 20.634792 | R213: 245.03815 | S213: 82.539167 | T213: 5.158698 | U213: 181 | V213: =((O213+R213)*100)/N213 | W213: =((P213+S213)*100)/N213 | X213: =((Q213+T213)*100)/N213
A214: 212 | B214: =C214+D214+E214+F214+G214+H214 | C214: 134.12615 | D214: 23.214141 | E214: 20.634792 | F214: 2.579349 | G214: 18.055443 | H214: 2.579349 | I214: =(100*B214)/N214 | J214: =((C214+F214)*100)/B214 | K214: =((D214+G214)*100)/B214 | L214: =((E214+H214)*100)/B214 | N214: =O214+P214+Q214+R214+S214+T214 | O214: 283.72839 | P214: 165.07833 | Q214: 23.214141 | R214: 188.29248 | S214: 108.33266 | T214: 15.476094 | U214: 173 | V214: =((O214+R214)*100)/N214 | W214: =((P214+S214)*100)/N214 | X214: =((Q214+T214)*100)/N214
... A302: 300 | B302: =C302+D302+E302+F302+G302+H302 | C302: 82.539167 | D302: 0 | E302: 10.317396 | F302: 46.428282 | G302: 0 | H302: 2.579349 | I302: =(100*B302)/N302 | J302: =((C302+F302)*100)/B302 | K302: =((D302+G302)*100)/B302 | L302: =((E302+H302)*100)/B302 | N302: =O302+P302+Q302+R302+S302+T302 | O302: 183.13378 | P302: 118.65005 | Q302: 46.428282 | R302: 247.6175 | S302: 149.60224 | T302: 98.015261 | U302: 83 | V302: =((O302+R302)*100)/N302 | W302: =((P302+S302)*100)/N302 | X302: =((Q302+T302)*100)/N302
A303: 301
A304: 302
A305: 303
A306: 304
A307: 305
A308: 306
A309: 307
A310: 308
A311: 309
A312: 310
A313: 311
...

Sheet IOS
A1: Segment | B1: Start | C1: Complete | D1: Fail | E1: Try again | L1: Complete | M1: LevelType | N1: =SUM(N3:N302) | O1: =(N1/C3)/300 | Q1: =AVERAGE(Q3:Q402) | R1: =AVERAGE(R3:R402) | S1: =AVERAGE(S3:S402) | T1: =AVERAGE(T13:T302) | U1: =AVERAGE(U3:U402) | V1: =AVERAGE(V3:V402) | W1: =AVERAGE(W3:W402) | X1: =AVERAGE(X3:X402) | Y1: =AVERAGE(Y3:Y402) | Z1: =AVERAGE(Z3:Z402) | AA1: =AVERAGE(AA3:AA402) | AB1: =AVERAGE(AB3:AB402) | ... AL1: =AVERAGE(AL3:AL402)
A2: Level | B2: Active users | C2: Active users | D2: Active users | E2: Active users | F2: Complete rate | G2: Fail Rate | H2: Drop 1 | I2: Uncomplete | J2: Drop 2 | K2: % | L2: avarage_attempt | M2: LevelType | N2: Total $ | O2: ARPU | P2: %_used_booster | Q2: avg_used_booster | R2: avg_owned_booster | S2: Avg. Thinking Time | T2: Avg.Rewarded | U2: Playon | V2: Time | W2: timer_spent_with_playon | X2: time_spent_without_playon | Y2: Avg_thinktime | Z2: coin_owned | AA2: coin_spent | AB2: Total users | AC2: Total users | AD2: Total users | AE2: Total users | AF2: Total users | AG2: Total users | AH2: Total users | AI2: Total users | AJ2: Total | AK2: Avg,Coin | AL2: coin owned
A3: 1 | B3: 4194 | C3: 4132 | D3: 75 | E3: 88 | F3: =(C3*100)/B3 | G3: =(D3*100)/B3 | H3: =((B3-B4)/B3)*100 | I3: =((B3-C3)/B3)*100 | J3: =((C3-B4)/C3)*100 | K3: =100-(((C3-C4)/C3)*100) | L3: 1.0080997 | M3: Normal | N3: 20.61 | O3: =N3/C3 | P3: =(Boosters_IOS!B3*100)/Boosters_And!N3 | Q3: =Boosters_IOS!B3/(C3+D3) | R3: =Boosters_IOS!N3/B3 | S3: 0.09470405 | T3: 0 | U3: 957712.28 | V3: 0.0034722222 | W3: 4286.4129 | X3: 4286.4129 | Y3: 5.8689655 | Z3: 589920.81 | AA3: 0 | AB3: 0 | AC3: 0 | AD3: 0 | AE3: 0 | AF3: 0 | AG3: 0 | AH3: 0 | AI3: 0 | AJ3: =AB3+AC3+AD3+AE3+AF3+AG3+AH3+AI3 | AK3: =AL3/C3 | AL3: 280300
A4: 2 | B4: 4117 | C4: 4065 | D4: 34 | E4: 49 | F4: =(C4*100)/B4 | G4: =(D4*100)/B4 | H4: =((B4-B5)/B4)*100 | I4: =((B4-C4)/B4)*100 | J4: =((C4-B5)/C4)*100 | K4: =100-(((C3-C5)/C3)*100) | L4: 1.0037975 | M4: Normal | N4: 5.1 | O4: =N4/C4 | P4: =(Boosters_IOS!B4*100)/Boosters_And!N4 | Q4: =Boosters_IOS!B4/(C4+D4) | R4: =Boosters_IOS!N4/B4 | S4: 0.0069620253 | T4: 0 | U4: 1060215.6 | V4: 0.0034722222 | W4: 10409.86 | X4: 10409.86 | Y4: 2.8493151 | Z4: 623039.17 | AA4: 0 | AB4: 0 | AC4: 0 | AD4: 0 | AE4: 0 | AF4: 0 | AG4: 0 | AH4: 0 | AI4: 0 | AJ4: =AB4+AC4+AD4+AE4+AF4+AG4+AH4+AI4 | AK4: =AL4/C4 | AL4: 295580
A5: 3 | B5: 4073 | C5: 4037 | D5: 44 | E5: 72 | F5: =(C5*100)/B5 | G5: =(D5*100)/B5 | H5: =((B5-B6)/B5)*100 | I5: =((B5-C5)/B5)*100 | J5: =((C5-B6)/C5)*100 | K5: =100-(((C3-C6)/C3)*100) | L5: 1.0044643 | M5: Normal | N5: 34.09 | O5: =N5/C5 | P5: =(Boosters_IOS!B5*100)/Boosters_And!N5 | Q5: =Boosters_IOS!B5/(C5+D5) | R5: =Boosters_IOS!N5/B5 | S5: 4.8839286 | T5: 0 | U5: 1163183.2 | V5: 0.0034722222 | W5: 14497.907 | X5: 14497.907 | Y5: 3.94 | Z5: 655640.05 | AA5: 0 | AB5: 0 | AC5: 0 | AD5: 0 | AE5: 0 | AF5: 0 | AG5: 0 | AH5: 0 | AI5: 0 | AJ5: =AB5+AC5+AD5+AE5+AF5+AG5+AH5+AI5 | AK5: =AL5/C5 | AL5: 310880
A6: 4 | B6: 4032 | C6: 4001 | D6: 44 | E6: 49 | F6: =(C6*100)/B6 | G6: =(D6*100)/B6 | H6: =((B6-B7)/B6)*100 | I6: =((B6-C6)/B6)*100 | J6: =((C6-B7)/C6)*100 | K6: =100-(((C3-C7)/C3)*100) | L6: 1.005148 | M6: Normal | N6: 16.77 | O6: =N6/C6 | P6: =(Boosters_IOS!B6*100)/Boosters_And!N6 | Q6: =Boosters_IOS!B6/(C6+D6) | R6: =Boosters_IOS!N6/B6 | S6: 4.2072072 | T6: 0 | U6: 1260579.4 | V6: 0.0034722222 | W6: 26037.586 | X6: 26037.586 | Y6: 3.033557 | Z6: 667886.95 | AA6: 0 | AB6: 0 | AC6: 0 | AD6: 0 | AE6: 0 | AF6: 0 | AG6: 0 | AH6: 0 | AI6: 0 | AJ6: =AB6+AC6+AD6+AE6+AF6+AG6+AH6+AI6 | AK6: =AL6/C6 | AL6: 330980
A7: 5 | B7: 3995 | C7: 3964 | D7: 31 | E7: 46 | F7: =(C7*100)/B7 | G7: =(D7*100)/B7 | H7: =((B7-B8)/B7)*100 | I7: =((B7-C7)/B7)*100 | J7: =((C7-B8)/C7)*100 | K7: =100-(((C3-C8)/C3)*100) | L7: 1.0051982 | M7: Normal | N7: 8.29 | O7: =N7/C7 | P7: =(Boosters_IOS!B7*100)/Boosters_And!N7 | Q7: =Boosters_IOS!B7/(C7+D7) | R7: =Boosters_IOS!N7/B7 | S7: 3.5977908 | T7: 3 | U7: 1334838.9 | V7: 0.0034722222 | W7: 31307.201 | X7: 31307.201 | Y7: 2.5068493 | Z7: 680478.82 | AA7: 0 | AB7: 0 | AC7: 0 | AD7: 0 | AE7: 0 | AF7: 0 | AG7: 0 | AH7: 0 | AI7: 0 | AJ7: =AB7+AC7+AD7+AE7+AF7+AG7+AH7+AI7 | AK7: =AL7/C7 | AL7: 344990
A8: 6 | B8: 3970 | C8: 3895 | D8: 103 | E8: 126 | F8: =(C8*100)/B8 | G8: =(D8*100)/B8 | H8: =((B8-B9)/B8)*100 | I8: =((B8-C8)/B8)*100 | J8: =((C8-B9)/C8)*100 | K8: =100-(((C3-C9)/C3)*100) | L8: 1.0138889 | M8: Normal | N8: 15.92 | O8: =N8/C8 | P8: =(Boosters_IOS!B8*100)/Boosters_And!N8 | Q8: =Boosters_IOS!B8/(C8+D8) | R8: =Boosters_IOS!N8/B8 | S8: 4.7949735 | T8: 10 | U8: 1411239.2 | V8: 0.0034722222 | W8: 65460.51 | X8: 65460.51 | Y8: 5.3669065 | Z8: 672371.72 | AA8: 0 | AB8: 0 | AC8: 0 | AD8: 0 | AE8: 0 | AF8: 0 | AG8: 0 | AH8: 0 | AI8: 0 | AJ8: =AB8+AC8+AD8+AE8+AF8+AG8+AH8+AI8 | AK8: =AL8/C8 | AL8: 357210
A9: 7 | B9: 3892 | C9: 3843 | D9: 67 | E9: 98 | F9: =(C9*100)/B9 | G9: =(D9*100)/B9 | H9: =((B9-B10)/B9)*100 | I9: =((B9-C9)/B9)*100 | J9: =((C9-B10)/C9)*100 | K9: =100-(((C3-C10)/C3)*100) | L9: 1.0053583 | M9: Normal | N9: 22.94 | O9: =N9/C9 | P9: =(Boosters_IOS!B9*100)/Boosters_And!N9 | Q9: =Boosters_IOS!B9/(C9+D9) | R9: =Boosters_IOS!N9/B9 | S9: 4.3583389 | T9: 0 | U9: 1480623.7 | V9: 0.0034722222 | W9: 17447.512 | X9: 17447.512 | Y9: 6.0215827 | Z9: 700487.83 | AA9: 0 | AB9: 0 | AC9: 0 | AD9: 0 | AE9: 0 | AF9: 0 | AG9: 0 | AH9: 0 | AI9: 0 | AJ9: =AB9+AC9+AD9+AE9+AF9+AG9+AH9+AI9 | AK9: =AL9/C9 | AL9: 369730
A10: 8 | B10: 3843 | C10: 3820 | D10: 54 | E10: 77 | F10: =(C10*100)/B10 | G10: =(D10*100)/B10 | H10: =((B10-B11)/B10)*100 | I10: =((B10-C10)/B10)*100 | J10: =((C10-B11)/C10)*100 | K10: =100-(((C3-C11)/C3)*100) | L10: 1.004717 | M10: Normal | N10: 0 | O10: =N10/C10 | P10: =(Boosters_IOS!B10*100)/Boosters_And!N10 | Q10: =Boosters_IOS!B10/(C10+D10) | R10: =Boosters_IOS!N10/B10 | S10: 4.9454178 | T10: 0 | U10: 1552793.9 | V10: 0.0034722222 | W10: 31583.187 | X10: 31583.187 | Y10: 16.195652 | Z10: 722566.74 | AA10: 0 | AB10: 8 | AC10: 0 | AD10: 0 | AE10: 0 | AF10: 0 | AG10: 0 | AH10: 0 | AI10: 0 | AJ10: =AB10+AC10+AD10+AE10+AF10+AG10+AH10+AI10 | AK10: =AL10/C10 | AL10: 383010
A11: 9 | B11: 3820 | C11: 3792 | D11: 142 | E11: 162 | F11: =(C11*100)/B11 | G11: =(D11*100)/B11 | H11: =((B11-B12)/B11)*100 | I11: =((B11-C11)/B11)*100 | J11: =((C11-B12)/C11)*100 | K11: =100-(((C3-C12)/C3)*100) | L11: 1.0251359 | M11: Normal | N11: 7.06 | O11: =N11/C11 | P11: =(Boosters_IOS!B11*100)/Boosters_And!N11 | Q11: =Boosters_IOS!B11/(C11+D11) | R11: =Boosters_IOS!N11/B11 | S11: 4.5407609 | T11: 8 | U11: 1616581.2 | V11: 0.0020833333 | W11: 75568.51 | X11: 75568.51 | Y11: 8 | Z11: 672199.23 | AA11: 0 | AB11: 0 | AC11: 0 | AD11: 0 | AE11: 0 | AF11: 0 | AG11: 0 | AH11: 0 | AI11: 0 | AJ11: =AB11+AC11+AD11+AE11+AF11+AG11+AH11+AI11 | AK11: =AL11/C11 | AL11: 397250
A12: 10 | B12: 3709 | C12: 3696 | D12: 34 | E12: 31 | F12: =(C12*100)/B12 | G12: =(D12*100)/B12 | H12: =((B12-B13)/B12)*100 | I12: =((B12-C12)/B12)*100 | J12: =((C12-B13)/C12)*100 | K12: =100-(((C3-C13)/C3)*100) | L12: 1.013947 | M12: Normal | N12: 12.45 | O12: =N12/C12 | P12: =(Boosters_IOS!B12*100)/Boosters_And!N12 | Q12: =Boosters_IOS!B12/(C12+D12) | R12: =Boosters_IOS!N12/B12 | S12: 2.7405858 | T12: 15 | U12: 1664144.4 | V12: 0.00092592593 | W12: 32678.508 | X12: 32652.634 | Y12: 6.9215686 | Z12: 574914.05 | AA12: 7762.1159 | AB12: 0 | AC12: 0 | AD12: 0 | AE12: 0 | AF12: 0 | AG12: 0 | AH12: 0 | AI12: 0 | AJ12: =AB12+AC12+AD12+AE12+AF12+AG12+AH12+AI12 | AK12: =AL12/C12 | AL12: 411960
A13: 11 | B13: 3562 | C13: 3464 | D13: 720 | E13: 642 | F13: =(C13*100)/B13 | G13: =(D13*100)/B13 | H13: =((B13-B14)/B13)*100 | I13: =((B13-C13)/B13)*100 | J13: =((C13-B14)/C13)*100 | K13: =100-(((C3-C14)/C3)*100) | L13: 1.1489203 | M13: Normal | N13: 47.04 | O13: =N13/C13 | P13: =(Boosters_IOS!B13*100)/Boosters_And!N13 | Q13: =Boosters_IOS!B13/(C13+D13) | R13: =Boosters_IOS!N13/B13 | S13: 2.9381981 | T13: 591 | U13: 2821214.5 | V13: 0.0011574074 | W13: 42812.381 | X13: 42579.518 | Y13: 6.0689655 | Z13: 725412.85 | AA13: 23286.348 | AB13: 0 | AC13: 0 | AD13: 0 | AE13: 0 | AF13: 0 | AG13: 0 | AH13: 0 | AI13: 0 | AJ13: =AB13+AC13+AD13+AE13+AF13+AG13+AH13+AI13 | AK13: =AL13/C13 | AL13: 620340
A14: 12 | B14: 3320 | C14: 3304 | D14: 18 | E14: 26 | F14: =(C14*100)/B14 | G14: =(D14*100)/B14 | H14: =((B14-B15)/B14)*100 | I14: =((B14-C14)/B14)*100 | J14: =((C14-B15)/C14)*100 | K14: =100-(((C3-C15)/C3)*100) | L14: 1.0054645 | M14: Normal | N14: 96.33 | O14: =N14/C14 | P14: =(Boosters_IOS!B14*100)/Boosters_And!N14 | Q14: =Boosters_IOS!B14/(C14+D14) | R14: =Boosters_IOS!N14/B14 | S14: 0.0054644809 | T14: 340 | U14: 3081548.2 | V14: 0.0017361111 | W14: 41579.067 | X14: 41579.067 | Y14: 2.1341463 | Z14: 723601.69 | AA14: 0 | AB14: 0 | AC14: 0 | AD14: 0 | AE14: 0 | AF14: 0 | AG14: 0 | AH14: 0 | AI14: 0 | AJ14: =AB14+AC14+AD14+AE14+AF14+AG14+AH14+AI14 | AK14: =AL14/C14 | AL14: 666200
A15: 13 | B15: 3255 | C15: 3247 | D15: 10 | E15: 10 | F15: =(C15*100)/B15 | G15: =(D15*100)/B15 | H15: =((B15-B16)/B15)*100 | I15: =((B15-C15)/B15)*100 | J15: =((C15-B16)/C15)*100 | K15: =100-(((C3-C16)/C3)*100) | L15: 1.0039714 | M15: Normal | N15: 38.09 | O15: =N15/C15 | P15: =(Boosters_IOS!B15*100)/Boosters_And!N15 | Q15: =Boosters_IOS!B15/(C15+D15) | R15: =Boosters_IOS!N15/B15 | S15: 4.675139 | T15: 320 | U15: 3206208.2 | V15: 0.00092592593 | W15: 36870.05 | X15: 36775.18 | Y15: 6.7948718 | Z15: 705403.84 | AA15: 15524.232 | AB15: 0 | AC15: 0 | AD15: 0 | AE15: 0 | AF15: 0 | AG15: 0 | AH15: 0 | AI15: 0 | AJ15: =AB15+AC15+AD15+AE15+AF15+AG15+AH15+AI15 | AK15: =AL15/C15 | AL15: 685950
A16: 14 | B16: 3224 | C16: 3167 | D16: 684 | E16: 573 | F16: =(C16*100)/B16 | G16: =(D16*100)/B16 | H16: =((B16-B17)/B16)*100 | I16: =((B16-C16)/B16)*100 | J16: =((C16-B17)/C16)*100 | K16: =100-(((C3-C17)/C3)*100) | L16: 1.1962541 | M16: Hard | N16: 40.43 | O16: =N16/C16 | P16: =(Boosters_IOS!B16*100)/Boosters_And!N16 | Q16: =Boosters_IOS!B16/(C16+D16) | R16: =Boosters_IOS!N16/B16 | S16: 3.2728013 | T16: 408 | U16: 3079768.5 | V16: 0.0013888889 | W16: 40785.607 | X16: 40785.607 | Y16: 3.6794872 | Z16: 740764.59 | AA16: 7762.1159 | AB16: 0 | AC16: 0 | AD16: 0 | AE16: 0 | AF16: 0 | AG16: 0 | AH16: 0 | AI16: 0 | AJ16: =AB16+AC16+AD16+AE16+AF16+AG16+AH16+AI16 | AK16: =AL16/C16 | AL16: 646560
A17: 15 | B17: 3147 | C17: 3139 | D17: 80 | E17: 72 | F17: =(C17*100)/B17 | G17: =(D17*100)/B17 | H17: =((B17-B18)/B17)*100 | I17: =((B17-C17)/B17)*100 | J17: =((C17-B18)/C17)*100 | K17: =100-(((C3-C18)/C3)*100) | L17: 1.0230074 | M17: Normal | N17: 0 | O17: =N17/C17 | P17: =(Boosters_IOS!B17*100)/Boosters_And!N17 | Q17: =Boosters_IOS!B17/(C17+D17) | R17: =Boosters_IOS!N17/B17 | S17: 3.2711586 | T17: 291 | U17: 3159650.9 | V17: 0.0011574074 | W17: 34567.289 | X17: 34567.289 | Y17: 5.8133333 | Z17: 743869.44 | AA17: 0 | AB17: 0 | AC17: 0 | AD17: 0 | AE17: 0 | AF17: 0 | AG17: 0 | AH17: 0 | AI17: 0 | AJ17: =AB17+AC17+AD17+AE17+AF17+AG17+AH17+AI17 | AK17: =AL17/C17 | AL17: 651180
A18: 16 | B18: 3087 | C18: 3062 | D18: 160 | E18: 152 | F18: =(C18*100)/B18 | G18: =(D18*100)/B18 | H18: =((B18-B19)/B18)*100 | I18: =((B18-C18)/B18)*100 | J18: =((C18-B19)/C18)*100 | K18: =100-(((C3-C19)/C3)*100) | L18: 1.0058972 | M18: Normal | N18: 3.98 | O18: =N18/C18 | P18: =(Boosters_IOS!B18*100)/Boosters_And!N18 | Q18: =Boosters_IOS!B18/(C18+D18) | R18: =Boosters_IOS!N18/B18 | S18: 0.34203875 | T18: 317 | U18: 3165402.9 | V18: 0.00092592593 | W18: 13833.815 | X18: 13833.815 | Y18: 1.6578947 | Z18: 825544.14 | AA18: 0 | AB18: 0 | AC18: 0 | AD18: 0 | AE18: 0 | AF18: 0 | AG18: 0 | AH18: 0 | AI18: 0 | AJ18: =AB18+AC18+AD18+AE18+AF18+AG18+AH18+AI18 | AK18: =AL18/C18 | AL18: 656630
A19: 17 | B19: 3002 | C19: 2989 | D19: 106 | E19: 59 | F19: =(C19*100)/B19 | G19: =(D19*100)/B19 | H19: =((B19-B20)/B19)*100 | I19: =((B19-C19)/B19)*100 | J19: =((C19-B20)/C19)*100 | K19: =100-(((C3-C20)/C3)*100) | L19: 1.0163934 | M19: Normal | N19: 9.97 | O19: =N19/C19 | P19: =(Boosters_IOS!B19*100)/Boosters_And!N19 | Q19: =Boosters_IOS!B19/(C19+D19) | R19: =Boosters_IOS!N19/B19 | S19: 4.1941329 | T19: 271 | U19: 3166099.3 | V19: 0.0017361111 | W19: 36801.054 | X19: 36801.054 | Y19: 6.5945946 | Z19: 834427.45 | AA19: 0 | AB19: 0 | AC19: 0 | AD19: 0 | AE19: 0 | AF19: 0 | AG19: 0 | AH19: 0 | AI19: 0 | AJ19: =AB19+AC19+AD19+AE19+AF19+AG19+AH19+AI19 | AK19: =AL19/C19 | AL19: 668830
A20: 18 | B20: 2969 | C20: 2964 | D20: 13 | E20: 13 | F20: =(C20*100)/B20 | G20: =(D20*100)/B20 | H20: =((B20-B21)/B20)*100 | I20: =((B20-C20)/B20)*100 | J20: =((C20-B21)/C20)*100 | K20: =100-(((C3-C21)/C3)*100) | L20: 1.0060923 | M20: Normal | N20: 18.45 | O20: =N20/C20 | P20: =(Boosters_IOS!B20*100)/Boosters_And!N20 | Q20: =Boosters_IOS!B20/(C20+D20) | R20: =Boosters_IOS!N20/B20 | S20: 3.227154 | T20: 281 | U20: 3257356.7 | V20: 0.0013888889 | W20: 28995.815 | X20: 28995.815 | Y20: 5.0746269 | Z20: 777677.76 | AA20: 0 | AB20: 0 | AC20: 0 | AD20: 0 | AE20: 0 | AF20: 0 | AG20: 0 | AH20: 0 | AI20: 0 | AJ20: =AB20+AC20+AD20+AE20+AF20+AG20+AH20+AI20 | AK20: =AL20/C20 | AL20: 681970
A21: 19 | B21: 2938 | C21: 2933 | D21: 13 | E21: 18 | F21: =(C21*100)/B21 | G21: =(D21*100)/B21 | H21: =((B21-B22)/B21)*100 | I21: =((B21-C21)/B21)*100 | J21: =((C21-B22)/C21)*100 | K21: =100-(((C3-C22)/C3)*100) | L21: 1.005277 | M21: Normal | N21: 22.59 | O21: =N21/C21 | P21: =(Boosters_IOS!B21*100)/Boosters_And!N21 | Q21: =Boosters_IOS!B21/(C21+D21) | R21: =Boosters_IOS!N21/B21 | S21: 3.5426561 | T21: 578 | U21: 3388284.4 | V21: 0.0011574074 | W21: 33722.081 | X21: 33722.081 | Y21: 3.546875 | Z21: 768880.7 | AA21: 0 | AB21: 0 | AC21: 0 | AD21: 0 | AE21: 0 | AF21: 0 | AG21: 0 | AH21: 0 | AI21: 0 | AJ21: =AB21+AC21+AD21+AE21+AF21+AG21+AH21+AI21 | AK21: =AL21/C21 | AL21: 713850
A22: 20 | B22: 2912 | C22: 2904 | D22: 162 | E22: 106 | F22: =(C22*100)/B22 | G22: =(D22*100)/B22 | H22: =((B22-B23)/B22)*100 | I22: =((B22-C22)/B22)*100 | J22: =((C22-B23)/C22)*100 | K22: =100-(((C3-C23)/C3)*100) | L22: 1.0213144 | M22: Normal | N22: 3.93 | O22: =N22/C22 | P22: =(Boosters_IOS!B22*100)/Boosters_And!N22 | Q22: =Boosters_IOS!B22/(C22+D22) | R22: =Boosters_IOS!N22/B22 | S22: 3.8907638 | T22: 369 | U22: 3382248.7 | V22: 0.00092592593 | W22: 30203.255 | X22: 30142.883 | Y22: 5.5636364 | Z22: 673734.41 | AA22: 15524.232 | AB22: 0 | AC22: 0 | AD22: 0 | AE22: 0 | AF22: 0 | AG22: 0 | AH22: 0 | AI22: 0 | AJ22: =AB22+AC22+AD22+AE22+AF22+AG22+AH22+AI22 | AK22: =AL22/C22 | AL22: 712820
A23: 21 | B23: 2822 | C23: 2814 | D23: 15 | E23: 26 | F23: =(C23*100)/B23 | G23: =(D23*100)/B23 | H23: =((B23-B24)/B23)*100 | I23: =((B23-C23)/B23)*100 | J23: =((C23-B24)/C23)*100 | K23: =100-(((C3-C24)/C3)*100) | L23: 1.004583 | M23: Normal | N23: 31.08 | O23: =N23/C23 | P23: =(Boosters_IOS!B23*100)/Boosters_And!N23 | Q23: =Boosters_IOS!B23/(C23+D23) | R23: =Boosters_IOS!N23/B23 | S23: 3.0054995 | T23: 681 | U23: 3666505.9 | V23: 0.0013888889 | W23: 33316.726 | X23: 33264.979 | Y23: 5.9444444 | Z23: 679685.36 | AA23: 7762.1159 | AB23: 0 | AC23: 0 | AD23: 0 | AE23: 8 | AF23: 0 | AG23: 0 | AH23: 0 | AI23: 0 | AJ23: =AB23+AC23+AD23+AE23+AF23+AG23+AH23+AI23 | AK23: =AL23/C23 | AL23: 761350
A24: 22 | B24: 2757 | C24: 2755 | D24: 31 | E24: 28 | F24: =(C24*100)/B24 | G24: =(D24*100)/B24 | H24: =((B24-B25)/B24)*100 | I24: =((B24-C24)/B24)*100 | J24: =((C24-B25)/C24)*100 | K24: =100-(((C3-C25)/C3)*100) | L24: 1.005618 | M24: Normal | N24: 19.57 | O24: =N24/C24 | P24: =(Boosters_IOS!B24*100)/Boosters_And!N24 | Q24: =Boosters_IOS!B24/(C24+D24) | R24: =Boosters_IOS!N24/B24 | S24: 4.3642322 | T24: 340 | U24: 3733027.3 | V24: 0.0011574074 | W24: 42251.784 | X24: 42036.17 | Y24: 4.4545455 | Z24: 706162.8 | AA24: 15524.232 | AB24: 0 | AC24: 8 | AD24: 0 | AE24: 0 | AF24: 0 | AG24: 0 | AH24: 0 | AI24: 0 | AJ24: =AB24+AC24+AD24+AE24+AF24+AG24+AH24+AI24 | AK24: =AL24/C24 | AL24: 770940
A25: 23 | B25: 2744 | C25: 2690 | D25: 405 | E25: 240 | F25: =(C25*100)/B25 | G25: =(D25*100)/B25 | H25: =((B25-B26)/B25)*100 | I25: =((B25-C25)/B25)*100 | J25: =((C25-B26)/C25)*100 | K25: =100-(((C3-C26)/C3)*100) | L25: 1.084372 | M25: Hard | N25: 31.99 | O25: =N25/C25 | P25: =(Boosters_IOS!B25*100)/Boosters_And!N25 | Q25: =Boosters_IOS!B25/(C25+D25) | R25: =Boosters_IOS!N25/B25 | S25: 5.4611697 | T25: 374 | U25: 3521727 | V25: 0.0016203704 | W25: 25019.887 | X25: 24795.648 | Y25: 6.2037037 | Z25: 723929.42 | AA25: 15524.232 | AB25: 0 | AC25: 0 | AD25: 0 | AE25: 0 | AF25: 0 | AG25: 0 | AH25: 0 | AI25: 0 | AJ25: =AB25+AC25+AD25+AE25+AF25+AG25+AH25+AI25 | AK25: =AL25/C25 | AL25: 744710
A26: 24 | B26: 2664 | C26: 2646 | D26: 204 | E26: 155 | F26: =(C26*100)/B26 | G26: =(D26*100)/B26 | H26: =((B26-B27)/B26)*100 | I26: =((B26-C26)/B26)*100 | J26: =((C26-B27)/C26)*100 | K26: =100-(((C3-C27)/C3)*100) | L26: 1.0428432 | M26: Normal | N26: 6.98 | O26: =N26/C26 | P26: =(Boosters_IOS!B26*100)/Boosters_And!N26 | Q26: =Boosters_IOS!B26/(C26+D26) | R26: =Boosters_IOS!N26/B26 | S26: 3.3028238 | T26: 302 | U26: 3682123.8 | V26: 0.0017361111 | W26: 38362.101 | X26: 38362.101 | Y26: 7.2244898 | Z26: 663212.43 | AA26: 0 | AB26: 0 | AC26: 0 | AD26: 0 | AE26: 0 | AF26: 0 | AG26: 0 | AH26: 0 | AI26: 0 | AJ26: =AB26+AC26+AD26+AE26+AF26+AG26+AH26+AI26 | AK26: =AL26/C26 | AL26: 764700
A27: 25 | B27: 2621 | C27: 2621 | D27: 3 | E27: 5 | F27: =(C27*100)/B27 | G27: =(D27*100)/B27 | H27: =((B27-B28)/B27)*100 | I27: =((B27-C27)/B27)*100 | J27: =((C27-B28)/C27)*100 | K27: =100-(((C3-C28)/C3)*100) | L27: 1.0049213 | M27: Normal | N27: 1.99 | O27: =N27/C27 | P27: =(Boosters_IOS!B27*100)/Boosters_And!N27 | Q27: =Boosters_IOS!B27/(C27+D27) | R27: =Boosters_IOS!N27/B27 | S27: 6.6338583 | T27: 261 | U27: 3744698.9 | V27: 0.0009837963 | W27: 4217.4163 | X27: 4217.4163 | Y27: 5.4042553 | Z27: 648895.64 | AA27: 0 | AB27: 0 | AC27: 0 | AD27: 0 | AE27: 0 | AF27: 0 | AG27: 0 | AH27: 0 | AI27: 0 | AJ27: =AB27+AC27+AD27+AE27+AF27+AG27+AH27+AI27 | AK27: =AL27/C27 | AL27: 773730
A28: 26 | B28: 2592 | C28: 2590 | D28: 0 | E28: 0 | F28: =(C28*100)/B28 | G28: =(D28*100)/B28 | H28: =((B28-B29)/B28)*100 | I28: =((B28-C28)/B28)*100 | J28: =((C28-B29)/C28)*100 | K28: =100-(((C3-C29)/C3)*100) | L28: 1.0079681 | M28: Normal | N28: 1.99 | O28: =N28/C28 | P28: =(Boosters_IOS!B28*100)/Boosters_And!N28 | Q28: =Boosters_IOS!B28/(C28+D28) | R28: =Boosters_IOS!N28/B28 | S28: 1.9940239 | T28: 253 | U28: 3804088.4 | V28: 0.0010416667 | W28: 19422.539 | X28: 19258.672 | Y28: 5.1304348 | Z28: 662522.46 | AA28: 7762.1159 | AB28: 8 | AC28: 0 | AD28: 8 | AE28: 0 | AF28: 0 | AG28: 0 | AH28: 0 | AI28: 0 | AJ28: =AB28+AC28+AD28+AE28+AF28+AG28+AH28+AI28 | AK28: =AL28/C28 | AL28: 786390
A29: 27 | B29: 2574 | C29: 2559 | D29: 487 | E29: 273 | F29: =(C29*100)/B29 | G29: =(D29*100)/B29 | H29: =((B29-B30)/B29)*100 | I29: =((B29-C29)/B29)*100 | J29: =((C29-B30)/C29)*100 | K29: =100-(((C3-C30)/C3)*100) | L29: 1.141994 | M29: Normal | N29: 10.23 | O29: =N29/C29 | P29: =(Boosters_IOS!B29*100)/Boosters_And!N29 | Q29: =Boosters_IOS!B29/(C29+D29) | R29: =Boosters_IOS!N29/B29 | S29: 2.9859013 | T29: 307 | U29: 3545405.5 | V29: 0.0011574074 | W29: 32230.03 | X29: 31936.794 | Y29: 7.5555556 | Z29: 645514.8 | AA29: 31048.463 | AB29: 8 | AC29: 0 | AD29: 0 | AE29: 0 | AF29: 0 | AG29: 8 | AH29: 0 | AI29: 0 | AJ29: =AB29+AC29+AD29+AE29+AF29+AG29+AH29+AI29 | AK29: =AL29/C29 | AL29: 734560
A30: 28 | B30: 2533 | C30: 2528 | D30: 5 | E30: 5 | F30: =(C30*100)/B30 | G30: =(D30*100)/B30 | H30: =((B30-B31)/B30)*100 | I30: =((B30-C30)/B30)*100 | J30: =((C30-B31)/C30)*100 | K30: =100-(((C3-C31)/C3)*100) | L30: 1.0081549 | M30: Normal | N30: 10.9 | O30: =N30/C30 | P30: =(Boosters_IOS!B30*100)/Boosters_And!N30 | Q30: =Boosters_IOS!B30/(C30+D30) | R30: =Boosters_IOS!N30/B30 | S30: 2.8470948 | T30: 253 | U30: 3676591.1 | V30: 0.0017361111 | W30: 33670.334 | X30: 33670.334 | Y30: 7.4772727 | Z30: 601615.73 | AA30: 24148.805 | AB30: 0 | AC30: 0 | AD30: 0 | AE30: 8 | AF30: 0 | AG30: 0 | AH30: 0 | AI30: 0 | AJ30: =AB30+AC30+AD30+AE30+AF30+AG30+AH30+AI30 | AK30: =AL30/C30 | AL30: 745250
A31: 29 | B31: 2515 | C31: 2510 | D31: 70 | E31: 46 | F31: =(C31*100)/B31 | G31: =(D31*100)/B31 | H31: =((B31-B32)/B31)*100 | I31: =((B31-C31)/B31)*100 | J31: =((C31-B32)/C31)*100 | K31: =100-(((C3-C32)/C3)*100) | L31: 1.0174717 | M31: Normal | N31: 19.46 | O31: =N31/C31 | P31: =(Boosters_IOS!B31*100)/Boosters_And!N31 | Q31: =Boosters_IOS!B31/(C31+D31) | R31: =Boosters_IOS!N31/B31 | S31: 3.5436793 | T31: 219 | U31: 3701894.6 | V31: 0.0011574074 | W31: 28116.109 | X31: 27684.88 | Y31: 2.175 | Z31: 491773.16 | AA31: 55197.268 | AB31: 0 | AC31: 0 | AD31: 0 | AE31: 0 | AF31: 0 | AG31: 0 | AH31: 0 | AI31: 0 | AJ31: =AB31+AC31+AD31+AE31+AF31+AG31+AH31+AI31 | AK31: =AL31/C31 | AL31: 746090
A32: 30 | B32: 2481 | C32: 2471 | D32: 90 | E32: 77 | F32: =(C32*100)/B32 | G32: =(D32*100)/B32 | H32: =((B32-B33)/B32)*100 | I32: =((B32-C32)/B32)*100 | J32: =((C32-B33)/C32)*100 | K32: =100-(((C3-C33)/C3)*100) | L32: 1.0292276 | M32: Normal | N32: 0.99 | O32: =N32/C32 | P32: =(Boosters_IOS!B32*100)/Boosters_And!N32 | Q32: =Boosters_IOS!B32/(C32+D32) | R32: =Boosters_IOS!N32/B32 | S32: 3.006263 | T32: 258 | U32: 3704912.4 | V32: 0.0011574074 | W32: 25856.47 | X32: 25597.733 | Y32: 4.6842105 | Z32: 464416.02 | AA32: 15524.232 | AB32: 0 | AC32: 0 | AD32: 0 | AE32: 0 | AF32: 0 | AG32: 0 | AH32: 8 | AI32: 0 | AJ32: =AB32+AC32+AD32+AE32+AF32+AG32+AH32+AI32 | AK32: =AL32/C32 | AL32: 753300
A33: 31 | B33: 2484 | C33: 2435 | D33: 753 | E33: 420 | F33: =(C33*100)/B33 | G33: =(D33*100)/B33 | H33: =((B33-B34)/B33)*100 | I33: =((B33-C33)/B33)*100 | J33: =((C33-B34)/C33)*100 | L33: 1.1830688 | M33: Normal | N33: 21.9 | O33: =N33/C33 | P33: =(Boosters_IOS!B33*100)/Boosters_And!N33 | Q33: =Boosters_IOS!B33/(C33+D33) | R33: =Boosters_IOS!N33/B33 | S33: 3.4962963 | T33: 312 | U33: 3312967.4 | V33: 0.0015046296 | W33: 12272.768 | X33: 12272.768 | Y33: 4.1052632 | Z33: 505727.72 | AA33: 0 | AB33: 0 | AC33: 0 | AD33: 0 | AE33: 0 | AF33: 0 | AG33: 0 | AH33: 0 | AI33: 0 | AJ33: =AB33+AC33+AD33+AE33+AF33+AG33+AH33+AI33 | AK33: =AL33/C33 | AL33: 665840
A34: 32 | B34: 2430 | C34: 2414 | D34: 258 | E34: 178 | F34: =(C34*100)/B34 | G34: =(D34*100)/B34 | H34: =((B34-B35)/B34)*100 | I34: =((B34-C34)/B34)*100 | J34: =((C34-B35)/C34)*100 | L34: 1.0512273 | M34: Normal | N34: 4.43 | O34: =N34/C34 | P34: =(Boosters_IOS!B34*100)/Boosters_And!N34 | Q34: =Boosters_IOS!B34/(C34+D34) | R34: =Boosters_IOS!N34/B34 | S34: 4.5229456 | T34: 286 | U34: 3317842.4 | V34: 0.0013888889 | W34: 26313.573 | X34: 26313.573 | Y34: 5.4473684 | Z34: 506262.45 | AA34: 0 | AB34: 0 | AC34: 0 | AD34: 0 | AE34: 0 | AF34: 8 | AG34: 0 | AH34: 0 | AI34: 0 | AJ34: =AB34+AC34+AD34+AE34+AF34+AG34+AH34+AI34 | AK34: =AL34/C34 | AL34: 653035
A35: 33 | B35: 2391 | C35: 2388 | D35: 248 | E35: 147 | F35: =(C35*100)/B35 | G35: =(D35*100)/B35 | H35: =((B35-B36)/B35)*100 | I35: =((B35-C35)/B35)*100 | J35: =((C35-B36)/C35)*100 | L35: 1.0625674 | M35: Normal | N35: 2.98 | O35: =N35/C35 | P35: =(Boosters_IOS!B35*100)/Boosters_And!N35 | Q35: =Boosters_IOS!B35/(C35+D35) | R35: =Boosters_IOS!N35/B35 | S35: 3.1445523 | T35: 294 | U35: 3241983.7 | V35: 0.0019675926 | W35: 39629.914 | X35: 39517.794 | Y35: 11.277778 | Z35: 479267.53 | AA35: 15524.232 | AB35: 8 | AC35: 0 | AD35: 8 | AE35: 0 | AF35: 8 | AG35: 0 | AH35: 0 | AI35: 8 | AJ35: =AB35+AC35+AD35+AE35+AF35+AG35+AH35+AI35 | AK35: =AL35/C35 | AL35: 639730
A36: 34 | B36: 2365 | C36: 2355 | D36: 72 | E36: 52 | F36: =(C36*100)/B36 | G36: =(D36*100)/B36 | H36: =((B36-B37)/B36)*100 | I36: =((B36-C36)/B36)*100 | J36: =((C36-B37)/C36)*100 | L36: 1.020765 | M36: Normal | N36: 10.98 | O36: =N36/C36 | P36: =(Boosters_IOS!B36*100)/Boosters_And!N36 | Q36: =Boosters_IOS!B36/(C36+D36) | R36: =Boosters_IOS!N36/B36 | S36: 3.3508197 | T36: 240 | U36: 3363006.8 | V36: 0.0023148148 | W36: 50384.756 | X36: 49867.282 | Y36: 7.7575758 | Z36: 415997.66 | AA36: 31048.463 | AB36: 0 | AC36: 0 | AD36: 0 | AE36: 0 | AF36: 0 | AG36: 0 | AH36: 0 | AI36: 0 | AJ36: =AB36+AC36+AD36+AE36+AF36+AG36+AH36+AI36 | AK36: =AL36/C36 | AL36: 645380
A37: 35 | B37: 2329 | C37: 2309 | D37: 340 | E37: 222 | F37: =(C37*100)/B37 | G37: =(D37*100)/B37 | H37: =((B37-B38)/B37)*100 | I37: =((B37-C37)/B37)*100 | J37: =((C37-B38)/C37)*100 | L37: 1.1113586 | M37: Normal | N37: 0 | O37: =N37/C37 | P37: =(Boosters_IOS!B37*100)/Boosters_And!N37 | Q37: =Boosters_IOS!B37/(C37+D37) | R37: =Boosters_IOS!N37/B37 | S37: 3.5222717 | T37: 291 | U37: 3214242.8 | V37: 0.00069444444 | W37: 2751.2388 | X37: 2751.2388 | Y37: 5.1875 | Z37: 414790.22 | AA37: 0 | AB37: 0 | AC37: 0 | AD37: 0 | AE37: 0 | AF37: 0 | AG37: 0 | AH37: 0 | AI37: 0 | AJ37: =AB37+AC37+AD37+AE37+AF37+AG37+AH37+AI37 | AK37: =AL37/C37 | AL37: 614495
A38: 36 | B38: 2298 | C38: 2296 | D38: 5 | E38: 13 | F38: =(C38*100)/B38 | G38: =(D38*100)/B38 | H38: =((B38-B39)/B38)*100 | I38: =((B38-C38)/B38)*100 | J38: =((C38-B39)/C38)*100 | L38: 1.0067265 | M38: Normal | N38: 2.98 | O38: =N38/C38 | P38: =(Boosters_IOS!B38*100)/Boosters_And!N38 | Q38: =Boosters_IOS!B38/(C38+D38) | R38: =Boosters_IOS!N38/B38 | S38: 6.3609865 | T38: 217 | U38: 3290166 | V38: 0.0010416667 | W38: 19655.402 | X38: 19569.157 | Y38: 6.5 | Z38: 420223.7 | AA38: 7762.1159 | AB38: 0 | AC38: 0 | AD38: 0 | AE38: 0 | AF38: 0 | AG38: 0 | AH38: 0 | AI38: 0 | AJ38: =AB38+AC38+AD38+AE38+AF38+AG38+AH38+AI38 | AK38: =AL38/C38 | AL38: 633570
A39: 37 | B39: 2288 | C39: 2288 | D39: 5 | E39: 8 | F39: =(C39*100)/B39 | G39: =(D39*100)/B39 | H39: =((B39-B40)/B39)*100 | I39: =((B39-C39)/B39)*100 | J39: =((C39-B40)/C39)*100 | L39: 1.0134983 | M39: Normal | N39: 3.98 | O39: =N39/C39 | P39: =(Boosters_IOS!B39*100)/Boosters_And!N39 | Q39: =Boosters_IOS!B39/(C39+D39) | R39: =Boosters_IOS!N39/B39 | S39: 2.3700787 | T39: 201 | U39: 3384157.4 | V39: 0.00092592593 | W39: 11332.689 | X39: 11332.689 | Y39: 6.28125 | Z39: 430918.17 | AA39: 0 | AB39: 0 | AC39: 8 | AD39: 8 | AE39: 0 | AF39: 0 | AG39: 0 | AH39: 0 | AI39: 0 | AJ39: =AB39+AC39+AD39+AE39+AF39+AG39+AH39+AI39 | AK39: =AL39/C39 | AL39: 640875
A40: 38 | B40: 2272 | C40: 2272 | D40: 5 | E40: 10 | F40: =(C40*100)/B40 | G40: =(D40*100)/B40 | H40: =((B40-B41)/B40)*100 | I40: =((B40-C40)/B40)*100 | J40: =((C40-B41)/C40)*100 | L40: 1.011325 | M40: Normal | N40: 25.94 | O40: =N40/C40 | P40: =(Boosters_IOS!B40*100)/Boosters_And!N40 | Q40: =Boosters_IOS!B40/(C40+D40) | R40: =Boosters_IOS!N40/B40 | S40: 2.7032843 | T40: 237 | U40: 3462763.1 | V40: 0.0013888889 | W40: 25338.996 | X40: 25140.631 | Y40: 7.1034483 | Z40: 359489.46 | AA40: 48297.61 | AB40: 0 | AC40: 0 | AD40: 0 | AE40: 0 | AF40: 0 | AG40: 0 | AH40: 0 | AI40: 0 | AJ40: =AB40+AC40+AD40+AE40+AF40+AG40+AH40+AI40 | AK40: =AL40/C40 | AL40: 656415
...

Sheet Boosters_IOS
A1: Segment | C1: Complete | D1: Complete | E1: Complete | F1: Fail | G1: Fail | H1: Fail | J1: Complete | K1: Column 1 | L1: Column 2 | M1: Column 3 | O1: Complete | P1: Complete | Q1: Complete | R1: Fail | S1: Fail | T1: Fail | V1: Complete | W1: Column 1 | X1: Column 2
A2: Level | B2: Total USED Booster | C2: Booster A used | D2: Booster B used | E2: Booster C used | F2: Booster A used | G2: Booster B used | H2: Booster C used | I2: %_used_booster | J2: %_A_used | K2: %_B_used | L2: %_C_used | M2: Total not USED Booster | N2: Total OWNED Booster | O2: Booster A owned | P2: Booster B owned | Q2: Booster C owned | R2: Booster A owned | S2: Booster B owned | T2: Booster C owned | U2: Total Rewarded | V2: %_A_owned | W2: %_B_owned | X2: %_C_owned
A3: 1 | B3: =C3+D3+E3+F3+G3+H3 | C3: 0 | D3: 0 | E3: 0 | F3: 0 | G3: 0 | H3: 0 | I3: =(100*B3)/N3 | J3: =((C3+F3)*100)/B3 | K3: =((D3+G3)*100)/B3 | L3: =((E3+H3)*100)/B3 | N3: =O3+P3+Q3+R3+S3+T3 | O3: 0 | P3: 0 | Q3: 0 | R3: 0 | S3: 0 | T3: 0 | U3: 0 | V3: =((O3+R3)*100)/N3 | W3: =((P3+S3)*100)/N3 | X3: =((Q3+T3)*100)/N3
